Workbook
Name \a: #REF!
Name \a: #REF!
Name \a: #REF!
Name \a: #REF!
Name \a: #REF!
Name \C: #REF!
Name \C: #REF!
Name \C: #REF!
Name \C: #REF!
Name \C: #REF!
Name \d: #REF!
Name \d: #REF!
Name \d: #REF!
Name \d: #REF!
Name \d: #REF!
Name \L: #REF!
Name \L: #REF!
Name \L: #REF!
Name \L: #REF!
Name \L: #REF!
Name \p: #REF!
Name \p: #REF!
Name \p: #REF!
Name \p: #REF!
Name \p: #REF!
Name \s: #REF!
Name \s: #REF!
Name \s: #REF!
Name \s: #REF!
Name \s: #REF!
Name \z: #REF!
Name \z: #REF!
Name \z: #REF!
Name \z: #REF!
Name \z: #REF!
Name _.dbf: #REF!
Name _.dbf: #REF!
Name _.dbf: #REF!
Name _.dbf: #REF!
Name _.dbf: #REF!
Name _?: #REF!
Name _?: #REF!
Name _?: #REF!
Name _?: #REF!
Name _?: #REF!
Name _??????: #REF!
Name _??????: #REF!
Name _??????: #REF!
Name _??????: #REF!
Name _??????: #REF!
Name __?: #REF!
Name __?: #REF!
Name __?: #REF!
Name __?: #REF!
Name __?: #REF!
Name __??????: #REF!
Name __??????: #REF!
Name __??????: #REF!
Name __??????: #REF!
Name __??????: #REF!

Sheet args
A1: {'TemplateId':'$TemplateId$'}
A2: {'TableCode':'GZD','TableName':'T00','ColumnCounts':'7','ColumnNames':'A;B;C;D;E;F;G;'}
A3: {'TableCode':'ZZ','TableName':'T01','ColumnCounts':'10','ColumnNames':'A;B;C;D;E;F;G;H;I;J'}
A4: {'TableCode':'XMJCXX','TableName':'T02','ColumnCounts':'87','ColumnNames':'A;B;C;D;E;F;G;H;I;J;K;L;M;N;O;P;Q;R;S;T;U;V;W;X;Y;Z;AA;AB;AC;AD;AE;AF;AG;AH;AI;AJ;AK;AL;AM;AN;AO;AP;AQ;AR;AS;AT;AU;AV;AW;AX;AY;AZ;BA;BB;BC;BD;BE;BF;BG;BH;BI;BJ;BK;BL;BM;BN;BO;BP;BQ;BR;BS;BT;BU;BV;BW;BX;BY;BZ;CA;CB;CC;CD;CE;CF;CG;CH;CI;CJ'}
A5: {'TableCode':'CBCS','TableName':'T03','ColumnCounts':'11','ColumnNames':'A;B;C;D;E;F;G;H;I;J;K'}
A6: {'TableCode':'MBCBKZ','TableName':'T04','ColumnCounts':'30','ColumnNames':'A;B;C;D;E;F;G;H;I;J;K;L;M;N;O;P;Q;R;S;T;U;V;W;X;Y;Z;AA;AB;AC;AD'}
A7: {'TableCode':'CBCSMX','TableName':'T05','ColumnCounts':'21','ColumnNames':'A;B;C;D;E;F;G;H;I;J;K;L;M;N;O;P;Q;R;S;T;U'}
A8: {'TableCode':'FXHBB','TableName':'T06','ColumnCounts':'12','ColumnNames':'A;B;C;D;E;F;G;H;I;J;K;L'}
A9: {'TableCode':'DSJCD','TableName':'T07','ColumnCounts':'236','ColumnNames':'COLA;COLB;COLC;COLD;COLE;COLF;COLG;COLH;COLI;COLJ;COLK;COLL;COLM;COLN;COLO;COLP;COLQ;COLR;COLS;COLT;COLU;COLV;COLW;COLX;COLY;COLZ;COLAA;COLAB;COLAC;COLAD;COLAE;COLAF;COLAG;COLAH;COLAI;COLAJ;COLAK;COLAL;COLAM;COLAN;COLAO;COLAP;COLAQ;COLAR;COLAS;COLAT;COLAU;COLAV;COLAW;COLAX;COLAY;COLAZ;COLBA;COLBB;COLBC;COLBD;COLBE;COLBF;COLBG;COLBH;COLBI;COLBJ;COLBK;COLBL;COLBM;COLBN;COLBO;COLBP;COLBQ;COLBR;COLBS;COLBT;COLBU;COLBV;COLBW;COLBX;COLBY;COLBZ;COLCA;COLCB;COLCC;COLCD;COLCE;COLCF;COLCG;COLCH;COLCI;COLCJ;COLCK;COLCL;COLCM;COLCN;COLCO;COLCP;COLCQ;COLCR;COLCS;COLCT;COLCU;COLCV;COLCW;COLCX;COLCY;COLCZ;COLDA;COLDB;COLDC;COL$pcode1$01;COL$pcode1$02;COL$pcode1$03;COL$pcode1$04;COL$pcode1$05;COL$pcode1$06;COL$pcode1$07;COL$pcode1$08;COL$pcode1$09;COL$pcode1$10;COL$pcode1$11;COL$pcode1$12;COL$pcode1$13;COL$pcode1$14;COL$pcode1$15;COL$pcode1$16;COL$pcode2$01;COL$pcode2$02;COL$pcode2$03;COL$pcode2$04;COL$pcode2$05;COL$pcode2$06;COL$pcode2$07;COL$pcode2$08;COL$pcode2$09;COL$pcode2$10;COL$pcode2$11;COL$pcode2$12;COL$pcode2$13;COL$pcode2$14;COL$pcode2$15;COL$pcode2$16;COL$pcode3$01;COL$pcode3$02;COL$pcode3$03;COL$pcode3$04;COL$pcode3$05;COL$pcode3$06;COL$pcode3$07;COL$pcode3$08;COL$pcode3$09;COL$pcode3$10;COL$pcode3$11;COL$pcode3$12;COL$pcode3$13;COL$pcode3$14;COL$pcode3$15;COL$pcode3$16;COL$pcode4$01;COL$pcode4$02;COL$pcode4$03;COL$pcode4$04;COL$pcode4$05;COL$pcode4$06;COL$pcode4$07;COL$pcode4$08;COL$pcode4$09;COL$pcode4$10;COL$pcode4$11;COL$pcode4$12;COL$pcode4$13;COL$pcode4$14;COL$pcode4$15;COL$pcode4$16;COL$pcode5$01;COL$pcode5$02;COL$pcode5$03;COL$pcode5$04;COL$pcode5$05;COL$pcode5$06;COL$pcode5$07;COL$pcode5$08;COL$pcode5$09;COL$pcode5$10;COL$pcode5$11;COL$pcode5$12;COL$pcode5$13;COL$pcode5$14;COL$pcode5$15;COL$pcode5$16;COL$pcode6$01;COL$pcode6$02;COL$pcode6$03;COL$pcode6$04;COL$pcode6$05;COL$pcode6$06;COL$pcode6$07;COL$pcode6$08;COL$pcode6$09;COL$pcode6$10;COL$pcode6$11;COL$pcode6$12;COL$pcode6$13;COL$pcode6$14;COL$pcode6$15;COL$pcode6$16;COLGV;COLGW;COLGX;COLGY;COLGZ;COLHA;COLHB;COLHC;COLHD;COLHE;COLHF;COLHG;COLHH;COLHI;COLHJ;COLHK;COLHL;COLHM;COLHN;COLHO;COLHP;COLHQ;COLHR;COLHS;COLHT;COLHU;COLHV;COLHW;COLHX;COLHY;COLHZ;COLIA;COLIB'}
A10: {'TableCode':'SFXHBB','TableName':'T08','ColumnCounts':'12','ColumnNames':'A;B;C;D;E;F;G;H;I;J;K;L'}
A11: {'TableCode':'DSJCDSY','TableName':'T09','ColumnCounts':'3','ColumnNames':'A;B;C;D'}

Sheet 00 成本测算关注点
A1: 苏州公司园区永旺北地块项目信息及特性交圈输入表
A2: 2022年4月版
A3: 本表随投资会成本测算资料同步提交，涉及影响成本的部分各职能线下交圈，由合约管理部填写，填写说明： ① 地块特征根据项目情况填写。 ② 风险描述：根据项目实际特性简要说明；如不涉及或无异常，可描述为“是”“否”“与以往一致”等。 ③ 落实措施：主要包括资料提供/数据交圈/指导意见，定性填写，描述大概金额，无需填写具体测算指标（测算指标在成本测算中体现即可）。如已有应对措施且风险可控，风险项选“否”；如风险较大不确定性或缺乏相应落实措施，风险项选“是”。 ④风险项：信息交圈责任部门为各协同职能部门，如有个别风险项难以确定，应征询协同部门意见。城市特征值征询投资、报建与设计意见。
A4: 序号 | B4: 协同职能 | C4: 事项 | D4: 事项特性 | E4: 是否涉及 | F4: 内容描述 | G4: 测算考虑
A5: 一、 | B5: 城市特征 | C5: 城市层级的通用政策，如政策、规范等与本年度城市特征值一致则无需额外修正
A6: =MAX(A$5:A5)+1 -> 1 | B6: 投资 | C6: 产业政策 | D6: 装配式政策 | E6: 与以往一致 | G6: 标准刻度：预制装配式面积____%，单体预制率____%，预制装配率____%
A7: =MAX(A$5:A6)+1 -> 2 | D7: 钢结构政策 | E7: 与以往一致 | G7: 标准刻度：XXXXXXXX
A8: =MAX(A$5:A7)+1 -> 3 | D8: 超低能耗政策 | E8: 与以往一致 | G8: 标准刻度：XXXXXXXX
A9: =MAX(A$5:A8)+1 -> 4 | D9: 绿色建筑政策 | E9: 与以往一致 | G9: 标准刻度：___星
A10: =MAX(A$5:A9)+1 -> 5 | D10: 全装修政策 | E10: 与以往一致 | G10: 基础装：成本XXX元/m2，售价XXXX元/m2，溢价率XXX% 升级装：成本XXXX元/m2，售价XXXX元/m2，溢价率XXX%
A11: =MAX(A$5:A10)+1 -> 6 | D11: 海绵城市 | E11: 与以往一致 | G11: 标准刻度：XXXXXXXX
A12: =MAX(A$5:A11)+1 -> 7 | D12: …
A13: =MAX(A$5:A12)+1 -> 8 | B13: 设计 | C13: 建筑规范 | D13: 常规配建面积规则 | E13: 与以往一致 | F13: 例：A社区用房：60m2每百户（含20m2每百户居家养老用房）；B物业经营：地上4‰；C物业办公：地上3‰；D公变：个数-（住宅面积*80/1000+商业面积*150/1000+办公面积*100/1000）/（800*4）；面积：160m2/个（20*8）；E专变：常规住宅1个，商业1个，面积160m2/个；F环网站：60m2/个；G电视机房：每500户15m2；H通信机房：70m2；I消控室：住宅和商业（集中商业（总建面9万m2）消控室面积约150m2）及办公均需单独设置消控室，常规60m2/个；J水泵房：规范查表
A14: =MAX(A$5:A13)+1 -> 9 | D14: 配建设施下地政策 | E14: 与以往一致
A15: =MAX(A$5:A14)+1 -> 10 | D15: 常规赠送率 | E15: 与以往一致 | F15: 阳台、飘窗、设备阳台、地下夹层、庭院
A16: =MAX(A$5:A15)+1 -> 11 | D16: 人防建设标准 | E16: 与以往一致 | F16: 新建民用住宅应修建人防比例10%，新建其他民用建筑应修建人防比例7% | G16: 是否异地建设，人防等级XXX, 单方增加___元/m2
A17: =MAX(A$5:A16)+1 -> 12 | D17: 车位配比 | E17: 与以往一致 | F17: 规范对车位个数的设置要求描述：按地上住宅建筑面积1.05个/100平方，非住宅为1.02个/100平方，商业为1.0个/100平方
A18: =MAX(A$5:A17)+1 -> 13 | D18: 常规地上车位占比 | E18: 与以往一致 | F18: 规范要求：不超过住宅户数的15%，不小于总车位的3% | G18: 户数的10%
A19: =MAX(A$5:A18)+1 -> 14 | D19: 充电设施 | E19: 与以往一致 | F19: 设备安装配比：_________ 预留容量和电线电缆：_________ | G19: 测算单方______元/m2
A20: =MAX(A$5:A19)+1 -> 15 | D20: 机械车位设置要求 | E20: 与以往一致
A21: =MAX(A$5:A20)+1 -> 16 | D21: 覆土深度要求 | E21: 与以往一致 | G21: 覆土深度：______m
A22: =MAX(A$5:A21)+1 -> 17 | D22: 消防配置要求 | E22: 与以往一致 | F22: 担架梯
A23: =MAX(A$5:A22)+1 -> 18 | D23: 节能配置要求 | E23: 与以往一致 | F23: 太阳能，空气能，常规保温，门窗要求
A24: 一、 | B24: 地块特征 | C24: 地块特殊信息
A25: 1 | B25: 投资 | C25: 出让条件 | D25: 品质政策 | E25: 否
A26: 2 | D26: 公建化立面政策 | E26: 是 | F26: 外立面材料至少为铝板
A27: 3 | D27: 未来社区要求 | E27: 否
A28: 4 | D28: 泛光照明要求 | E28: 是 | G28: 按照刻度计算
A29: 5 | D29: 配建要求 | E29: 否 | F29: 无
A30: 6 | D30: 文保建筑 | E30: 否 | F30: 无 | G30: 文物保护面积_________，测算单方_______元/m2
A31: 7 | D31: 地上拆迁 | E31: 否 | F31: 无 | G31: 场内建筑____m2 信号基站____处 公交站台____m2 高压电线____m
A32: 8 | D32: 地下拆迁 | E32: 否 | F32: 无 | G32: 地下管线：__________ 地下清障：__________
A33: 9 | D33: 地下通道/人行天桥联通要求 | E33: 否 | F33: 无 | G33: 地下连通道面积_______，测算单方_______元/m2 人行天桥面积_______，测算单方_______元/m2
A34: 10 | D34: ……
A35: 11 | C35: 地质地形及土壤条件 | D35: 场地自身高差 | E35: 否 | F35: 无 | G35: 场地高差，高差米数_____m 坡地建筑，测算单方____元/m2 挡土墙设置，测算____元/延米 室外电梯，测算____元/台，共____台
A36: 12 | D36: 场地表土/高堆土/场地平整 | E36: 否 | F36: 无 | G36: 场地堆土，堆土方量______m3
A37: 13 | D37: 土壤污染 | E37: 否 | F37: 无 | G37: 土壤治理：________
A38: 14 | D38: 不良地质/软弱地基/地下水位 | E38: 否 | F38: 无
A39: 15 | D39: 场地内淤泥 | E39: 否 | F39: 无 | G39: 淤泥面积________m2，深度______m
A40: 16 | D40: 场地内河道 | E40: 否 | F40: 无 | G40: 河道面积________m2，是/否涉及改道
...

Sheet 01 商业总则
A1: 总则
A2: 一、商业项目名词解释
A3: 分类 | C3: 指标名称 | D3: 指标分项 | E3: 单位 | F3: 设计控制值 | G3: 控制等级 | H3: 计算规则 | I3: 备注 | J3: 备注
A4: 用地规划指标 | C4: 建筑密度 | D4: 集中商业 | E4: - | F4: ≥60% | G4: 参考值 | I4: 住宅与商业同一块地时，争取地块间平衡覆盖率。 | J4: 《商业项目投资可研阶段方案设计控制参考指标》
C5: 绿化率 | D5: 集中商业 | E5: - | F5: ≥15% | G5: 参考值 | I5: 住宅与商业同一块地时，争取地块间平衡绿化率。
A6: 规划设计控制指标 | B6: 地库控制指标 | C6: 地库建筑面积 | E6: ㎡ | F6: - | H6: 地库建筑面积=地下商业面积+塔楼地下面积+地下车库面积+地下设备机房面积+配套面积+非机动车库面积 | I6: 1、塔楼地下面积指地库内塔楼核心筒及地下大堂面积。_x000D_ 2、地下车库面积指地下停车库及服务于停车库的设备用房面积。_x000D_ 3、地下设备机房面积指服务于商业的设备用房面积。_x000D_ 4、配套面积指地下物业管理用房、后勤用房；酒店项目中酒店后勤等辅助功能用房面积。
C7: 地下商业建筑面积 | E7: ㎡ | F7: - | H7: 即地下商业面积 | I7: - | J7: 成本测算需要_x000D_ 引用拆分指标
C8: 地下建筑面积（非商业） | E8: ㎡ | F8: - | H8: 地下建筑面积（非商业）=塔楼地下面积+地下车库面积+地下设备机房面积+配套面积+非机动车库面积 | I8: -
C9: 机动车单车位指标 | D9: 无人防或人防占地库面积≤10% | E9: ㎡/车位 | F9: 38 | G9: 强控值 | H9: 机动车单车位指标=地下车库面积/地下机动车位总数 | I9: 1、机械车位按一层车位计算停车位数。 | J9: 《商业项目投资可研阶段方案设计控制参考指标》
D10: 人防占地库面积＞10% | E10: ㎡/车位 | F10: 40 | G10: 强控值
C11: 地下设备机房面积配比 | D11: 集中商业 | E11: - | F11: 0.056 | G11: 强控值 | H11: 地下设备机房面积配比=地下设备机房面积/商业业态建筑面积 | I11: 1、商业业态建筑面积指集中商业、写字楼、酒店项目中对应各业态的地上、地下建筑面积之和，不含停车库、公共卸货平台、主要设备机房及地下部分的后勤服务及疏散等建筑面积。
D12: 写字楼 | E12: - | F12: 3.5%_x000D_ （写字楼建筑面积8≥万平米） | G12: 强控值 | H12: 地下设备机房面积配比=地下设备机房面积/商业业态建筑面积 | I12: 1、商业业态建筑面积指集中商业、写字楼、酒店项目中对应各业态的地上、地下建筑面积之和，不含停车库、公共卸货平台、主要设备机房及地下部分的后勤服务及疏散等建筑面积。
E13: - | F13: 4%_x000D_ （写字楼建筑面积5-8万平米） | G13: 强控值
E14: - | F14: 4.5%_x000D_ （写字楼建筑面积≤5万平米） | G14: 强控值
D15: 酒店 | E15: - | F15: 0.08 | G15: 强控值
B16: 集中_x000D_ 商业 | C16: 得铺率 | E16: - | F16: 0.57 | G16: 强控值 | H16: 综合得铺率=可租赁建筑面积/商业建筑面积 | I16: 1、商业建筑面积（GFA）：指建设用地范围内各层商业建筑面积之和，不含停车库、公共卸货平台、主要设备机房及地下部分的后勤服务及疏散等建筑面积。_x000D_ 2、可租赁建筑面积（GLA）：店铺租赁面积加该店铺独立使用的垂直交通、疏散、机房、后勤区等辅助功能面积。（具体详见《集中商业设计指引及配置标准》） | J16: 《商业项目投资可研阶段方案设计控制参考指标》
C17: 地上商业建筑面积 | F17: - | G17: - | H17: 地上商业建筑面积 | I17: 即上述地上各层商业建筑面积之和 | J17: 成本测算需要_x000D_ 引用拆分指标
C18: 小铺率 | E18: % | H18: 小铺率=面积150m2以下的小铺数量/铺位总数量（数量比） | I18: 150m2以下店铺的数量占比 | J18: 《集中商业设计指引及配置标准》
C19: 主力店占比 | E19: % | H19: 主力店占比=主力店面积/可租赁建筑面积（面积比） | I19: 主力店指商管公司确认的主力店店铺类型，如影院、超市等
C20: 层高 | E20: m | F20: 负一层5.7_x000D_ 首层6_x000D_ 二层以上5.4 | G20: 参考值 | I20: 此项为可研阶段拿地方案参考值 | J20: 《商业项目投资可研阶段方案设计控制参考指标》
B21: 写字楼控制指标 | C21: 实用率 | D21: H≤100m | E21: - | F21: ≥75% | G21: 强控值 | H21: 综合实用率=办公可租赁总面积/（办公塔楼地上总建筑面积－避难区面积） | I21: 1、实用率计算中标准层公共走道计入公摊面积。 | J21: 《商业项目投资可研阶段方案设计控制参考指标》
D22: 100m＜H≤150m | E22: - | F22: ≥73% | G22: 强控值
D23: 150m＜H≤200m | E23: - | F23: ≥71% | G23: 强控值
C24: 层高 | E24: m | F24: 4.2~4.5 | G24: 参考值 | I24: 此项为可研阶段拿地方案参考值
C25: 标准层面积 | D25: H≤100m | E25: ㎡ | F25: 1500~2000 | G25: 参考值 | I25: 此项为可研阶段拿地方案参考值
D26: 100m＜H≤150m | E26: ㎡ | F26: 1800~2200 | G26: 参考值
D27: 150m＜H≤200m | E27: ㎡ | F27: 2000~2200 | G27: 参考值
C28: 办公可租赁总面积 | E28: ㎡ | F28: - | G28: - | I28: 各户套内有产权的建筑面积之和 | J28: 《写字楼设计指引及配置标准》
C29: 通风量 | E29: 次/h | F29: - | G29: - | I29: 单位时间内被排出或进入的空气数量
C30: 供电指标 | E30: w/㎡ | F30: - | G30: - | I30: 单位面积用电负荷
C31: 避难层面积 | E31: - | F31: - | G31: 参考值 | I31: 投资阶段进行写字楼项目面积指标测算时应考虑避难层面积。 | J31: 《商业项目投资可研阶段方案设计控制参考指标》
B32: 酒店控制指标 | C32: 酒店建筑面积 | D32: 五星级 | E32: ㎡ | F32: 30000~40000 | G32: 参考值 | H32: 酒店建筑面积=地上酒店建筑面积+地下酒店建筑面积_x000D_ _x000D_ _x000D_ 单客房面积=酒店建筑面积/总客房数 | I32: 1、酒店建筑面积：指地上酒店建筑面积与地下酒店建筑面积和，其中地下酒店建筑面积含为酒店配套的服务用房、设备用房、物业用房、后勤用房、库房、管井等，不含地下车库、人防。_x000D_ 2、自然间：指酒店客房的最小分隔单元，即一个BAY 。_x000D_ 3、钥匙间（key）：对应酒店经营管理中的术语，一个钥匙间可以包含几个自然间。_x000D_ 4、总客房数：对应钥匙间总数。5、单客房面积：每间客房平摊建筑面积。 | J32: 《商业项目投资可研阶段方案设计控制参考指标》
C33: 总客房数 | E33: 间 | F33: 250~350 | G33: 参考值
C34: 单客房面积 | E34: ㎡/key | F34: 125~140 | G34: 强控值
C35: 酒店建筑面积 | D35: 四星级 | E35: ㎡ | F35: 21600~30000 | G35: 参考值
C36: 总客房数 | E36: 间 | F36: 250~350 | G36: 参考值
C37: 单客房面积 | E37: ㎡/key | F37: 90~100 | G37: 强控值
C38: 酒店建筑面积 | D38: 三星级 | E38: ㎡ | F38: 9000~12000 | G38: 参考值
C39: 总客房数 | E39: 间 | F39: 200~250 | G39: 参考值
C40: 单客房面积 | E40: ㎡/key | F40: 55~65 | G40: 强控值
...

Sheet 02 项目基础信息（输入）
A1: 一、基础信息 | CI1: C020001
A2: 1、通用 | H2: 2、住宅 | O2: 3、集中商业 | V2: 4、写字楼 | AC2: 5、酒店 | CI2: C020002
A3: 序号 | B3: 编码 | C3: 基础信息 | D3: 指标值 | E3: 单位 | F3: 属性 | H3: 序号 | I3: 编码 | J3: 基础信息 | K3: 指标值 | L3: 单位 | M3: 属性 | O3: 序号 | P3: 编码 | Q3: 基础信息 | R3: 指标值 | S3: 单位 | T3: 属性 | V3: 序号 | W3: 编码 | X3: 基础信息 | Y3: 指标值 | Z3: 单位 | AA3: 属性 | AC3: 序号 | AD3: 编码 | AE3: 基础信息 | AF3: 指标值 | AG3: 单位 | AH3: 属性 | CI3: C020003
A4: 1 | B4: PJ.01.03 | C4: 总建筑面积 | D4: =C69+C96 -> 74626.755 | E4: ㎡ | F4: 通用 | H4: 1 | I4: PJ.02.10.01 | J4: 项目定档 | K4: U4 | M4: 住宅 | O4: 1 | P4: PJ.02.10.01 | Q4: 项目定档 | T4: 集中商业 | V4: 1 | W4: PJ.02.10.01 | X4: 项目定档 | AA4: 写字楼 | AC4: 1 | AD4: PJ.02.10.01 | AE4: 项目定档 | AH4: 酒店 | CI4: C020004
A5: =MAX(A4)+1 -> 2 | B5: PJ.01.01 | C5: 地上建筑面积 | D5: =D4-D6 -> 52694.835 | E5: ㎡ | F5: 通用 | H5: =MAX(H4)+1 -> 2 | I5: PJ.02.02.01 | J5: 总计容面积 | K5: =D69 -> 46561.065 | L5: ㎡ | M5: 住宅 | O5: 2 | P5: PJ.03.10 | Q5: 集中商业建筑面积 | R5: =C75 -> 0 | S5: ㎡ | T5: 集中商业 | V5: 2 | W5: PJ.04.10 | X5: 写字楼建筑面积 | Y5: =C78 -> 0 | Z5: ㎡ | AA5: 写字楼 | AC5: 2 | AD5: PJ.05.10 | AE5: 酒店总建筑面积 | AF5: =AF6+AF7 -> 0 | AG5: ㎡ | AH5: 酒店 | CI5: C020005
A6: =MAX(A5)+1 -> 3 | B6: PJ.01.02 | C6: 地下建筑面积 | D6: =C32+E96 -> 21931.92 | E6: ㎡ | F6: 通用 | H6: =MAX(H5)+1 -> 3 | I6: PJ.02.02.02 | J6: 地上计容面积 | K6: =K5-K7 -> 46561.065 | L6: ㎡ | M6: 住宅 | O6: =MAX(O5)+1 -> 3 | P6: PJ.03.10.01 | Q6: 集中商业（地下）建筑面积 | R6: =E75 -> 0 | S6: ㎡ | T6: 集中商业 | V6: =MAX(V5)+1 -> 3 | W6: PJ.04.11 | X6: 办公可租赁面积 | Y6: =H78 -> 0 | Z6: ㎡ | AA6: 写字楼 | AC6: =MAX(AC5)+1 -> 3 | AD6: PJ.05.10.01 | AE6: 酒店地上建筑面积 | AF6: =C81 -> 0 | AG6: ㎡ | AH6: 酒店 | CI6: C020006
A7: =MAX(A6)+1 -> 4 | B7: PJ.01.43 | C7: 总商业建筑面积 | D7: =C96-C72 -> 0 | E7: ㎡ | F7: 通用 | H7: =MAX(H6)+1 -> 4 | I7: PJ.02.02.03 | J7: 地下计容面积 | K7: =D32 -> 0 | L7: ㎡ | M7: 住宅 | O7: =MAX(O6)+1 -> 4 | P7: PJ.03.10.02 | Q7: 集中商业（地上）建筑面积 | R7: =D75 -> 0 | S7: ㎡ | T7: 集中商业 | V7: =MAX(V6)+1 -> 4 | W7: PJ.04.12 | X7: 写字楼租赁展示区面积 | Y7: =M78 -> 0 | Z7: ㎡ | AA7: 写字楼 | AC7: =MAX(AC6)+1 -> 4 | AD7: PJ.05.10.02 | AE7: 酒店地下建筑面积 | AG7: ㎡ | AH7: 酒店 | CI7: C020007
A8: =MAX(A7)+1 -> 5 | B8: PJ.01.03.01 | C8: 地上商业建筑面积 | D8: =D7-D9 -> 0 | E8: ㎡ | F8: 通用 | H8: =MAX(H7)+1 -> 5 | I8: PJ.02.01 | J8: 容积率 | K8: =IFERROR(K5/D13,0) -> 1.616 | L8: ㎡/㎡ | M8: 住宅 | O8: =MAX(O7)+1 -> 5 | P8: PJ.03.11 | Q8: 可租赁建筑面积 | R8: =H75 -> 0 | S8: ㎡ | T8: 集中商业 | V8: =MAX(V7)+1 -> 5 | W8: PJ.04.13 | X8: 避难区面积 | Y8: =N78 -> 0 | Z8: ㎡ | AA8: 写字楼 | AC8: =MAX(AC7)+1 -> 5 | AD8: PJ.05.11 | AE8: 客房总数 | AF8: =BN81+BP81+BR81+BT81 -> 0 | AG8: key | AH8: 酒店 | CI8: C020008
A9: =MAX(A8)+1 -> 6 | B9: PJ.01.03.02 | C9: 地下商业建筑面积 | D9: =E75+E84 -> 0 | E9: ㎡ | F9: 通用 | H9: =MAX(H8)+1 -> 6 | I9: PJ.01.12 | J9: 户数 | K9: =AC69 -> 301 | L9: 户 | M9: 住宅 | O9: =MAX(O8)+1 -> 6 | P9: PJ.03.11.01 | Q9: 地上可租赁建筑面积 | R9: =R8-R10 -> 0 | S9: ㎡ | T9: 集中商业 | V9: =MAX(V8)+1 -> 6 | W9: PJ.04.14 | X9: 实用率 | Y9: =IFERROR(Y6/(Y5-Y8),0) -> 0 | Z9: ㎡ | AA9: 写字楼 | AC9: =MAX(AC8)+1 -> 6 | AD9: PJ.05.12 | AE9: 套房总数 | AF9: =BT81+BR81 -> 0 | AG9: key | AH9: 酒店 | CI9: C020009
A10: =MAX(A9)+1 -> 7 | B10: PJ.01.06 | C10: 总建造面积 | D10: =I69+C96 -> 74626.755 | E10: ㎡ | F10: 通用 | H10: =MAX(H9)+1 -> 7 | I10: PJ.80.38 | J10: 可售率 | K10: =IFERROR(K11/D4,0) -> 0.61896119 | L10: % | M10: 住宅 | O10: =MAX(O9)+1 -> 7 | P10: PJ.03.11.02 | Q10: 地下可租赁建筑面积 | S10: ㎡ | T10: 集中商业 | V10: =MAX(V9)+1 -> 7 | W10: PJ.04.15 | X10: 标准层层高 | Y10: =V78 -> 0 | Z10: m | AA10: 写字楼 | AC10: =MAX(AC9)+1 -> 7 | AD10: PJ.05.13 | AE10: 单客房面积 | AF10: =IFERROR((AF6+AF7)/AF8,0) -> 0 | AG10: ㎡/key | AH10: 酒店 | CI10: C0200010
A11: =MAX(A10)+1 -> 8 | B11: PJ.01.04 | C11: 地上建造面积 | D11: =D10-D12 -> 52694.835 | E11: ㎡ | F11: 通用 | H11: =MAX(H10)+1 -> 8 | I11: PJ.01.14 | J11: 可售面积 | K11: =E69 -> 46191.065 | L11: ㎡ | M11: 住宅 | O11: =MAX(O10)+1 -> 8 | P11: PJ.03.13 | Q11: 公共区域精装面积 | R11: =AD75 -> 0 | S11: ㎡ | T11: 集中商业 | V11: =MAX(V10)+1 -> 8 | W11: PJ.04.16 | X11: 标准层净高 | Y11: =U78 -> 0 | Z11: m | AA11: 写字楼 | AC11: =MAX(AC10)+1 -> 8 | AD11: PJ.05.14 | AE11: 套房占比 | AF11: =IFERROR(AF9/AF8,0) -> 0 | AG11: % | AH11: 酒店 | CI11: C0200011
A12: =MAX(A11)+1 -> 9 | B12: PJ.01.05 | C12: 地下建造面积 | D12: =E96+I32 -> 21931.92 | E12: ㎡ | F12: 通用 | H12: =MAX(H11)+1 -> 9 | I12: PJ.02.03.01 | J12: 套内面积 | K12: =+F69 -> 46191.065 | L12: ㎡ | M12: 住宅 | O12: =MAX(O11)+1 -> 9 | P12: PJ.03.14 | Q12: 得铺率 | R12: =I75 -> 0 | S12: % | T12: 集中商业 | V12: =MAX(V11)+1 -> 9 | W12: PJ.04.17 | X12: 建筑高度 | Y12: =F78 -> 0 | Z12: m | AA12: 写字楼 | AC12: =MAX(AC11)+1 -> 9 | AD12: PJ.05.15 | AE12: 标准层层高 | AF12: =V81 -> 0 | AG12: m | AH12: 酒店 | CI12: C0200012
A13: =MAX(A12)+1 -> 10 | B13: PJ.80.37 | C13: 占地面积 | D13: =总指标!E4 -> 28812.54 | E13: ㎡ | F13: 通用 | H13: =MAX(H12)+1 -> 10 | I13: PJ.02.04.01 | J13: 得房率 | K13: =IFERROR(K12/D69,0) -> 0.99205345 | L13: % | M13: 住宅 | O13: =MAX(O12)+1 -> 10 | P13: PJ.03.15 | Q13: 小铺率 | R13: =J75 -> 0 | S13: % | T13: 集中商业 | V13: =MAX(V12)+1 -> 10 | W13: PJ.04.18 | X13: 结构高度 | Y13: =G78 -> 0 | Z13: m | AA13: 写字楼 | AC13: =MAX(AC12)+1 -> 10 | AD13: PJ.05.16 | AE13: 标准层净高 | AF13: =U81 -> 0 | AG13: m | AH13: 酒店 | CI13: C0200013
A14: =MAX(A13)+1 -> 11 | B14: PJ.01.20 | C14: 室外面积 | D14: =总指标!E55-K26 -> 18786.64 | E14: ㎡ | F14: 通用 | H14: =MAX(H13)+1 -> 11 | I14: PJ.02.02.04 | J14: 室外面积占比 （室外/占地） | K14: =IFERROR(D14/D13,0) -> 0.65202998 | L14: % | M14: 住宅 | O14: =MAX(O13)+1 -> 11 | P14: PJ.03.16 | Q14: 主力店占比 | R14: =K75 -> 0 | S14: % | T14: 集中商业 | V14: =MAX(V13)+1 -> 11 | W14: PJ.04.19 | X14: 通风量 | Y14: =P78 -> 0 | Z14: 次/h | AA14: 写字楼 | AC14: =MAX(AC13)+1 -> 11 | AD14: PJ.05.20 | AE14: 综合用电指标 | AF14: =Q81 -> 0 | AG14: （VA/㎡） | AH14: 酒店 | CI14: C0200014
A15: =MAX(A14)+1 -> 12 | B15: PJ.01.22 | C15: 基坑面积 | D15: 24661 | E15: ㎡ | F15: 通用 | H15: =MAX(H14)+1 -> 12 | I15: PJ.02.02.05 | J15: 绿地率 （规划指标） | K15: 0 | L15: % | M15: 住宅 | O15: =MAX(O14)+1 -> 12 | P15: PJ.04.12 | Q15: 商场租赁展示区面积 | R15: =L75 -> 0 | S15: ㎡ | T15: 集中商业 | V15: =MAX(V14)+1 -> 12 | W15: PJ.04.20 | X15: 综合用电指标 | Y15: =Q78 -> 0 | Z15: （VA/㎡） | AA15: 写字楼 | AC15: =MAX(AC14)+1 -> 12 | AD15: PJ.05.21 | AE15: 供冷指标 | AF15: =R81 -> 0 | AG15: w/㎡ | AH15: 酒店 | CI15: C0200015
A16: =MAX(A15)+1 -> 13 | B16: PJ.80.36 | C16: 基坑延米长度 | D16: =支护!F3 -> 861 | E16: 延米 | F16: 通用 | H16: =MAX(H15)+1 -> 13 | I16: PJ.02.02.06 | J16: 硬景占比 （硬景/室外） | K16: 0 | L16: % | M16: 住宅 | O16: =MAX(O15)+1 -> 13 | P16: PJ.04.20 | Q16: 综合用电指标 | R16: =Q75 -> 0 | S16: （VA/㎡） | T16: 集中商业 | V16: =MAX(V15)+1 -> 13 | W16: PJ.04.21 | X16: 供冷指标 | Y16: =R78 -> 0 | Z16: w/㎡ | AA16: 写字楼 | AC16: =MAX(AC15)+1 -> 13 | AD16: PJ.05.19 | AE16: 酒店星级 | AG16: - | AH16: 酒店 | CI16: C0200016
A17: =MAX(A16)+1 -> 14 | B17: PJ.80.40 | C17: 总装机容量 | E17: KVA | F17: 通用 | H17: =MAX(H16)+1 -> 14 | I17: PJ.02.02.07 | J17: 软景占比 （软景/室外） | K17: 0 | L17: % | M17: 住宅 | O17: =MAX(O16)+1 -> 14 | P17: PJ.04.21 | Q17: 供冷指标 | R17: =R75 -> 0 | S17: w/㎡ | T17: 集中商业 | V17: =MAX(V16)+1 -> 14 | W17: PJ.04.22 | X17: 行业认证 | Z17: - | AA17: 写字楼 | AC17: =MAX(AC16)+1 -> 14 | AD17: PJ.05.22 | AE17: 行业认证 | AG17: - | AH17: 酒店 | CI17: C0200017
A18: =MAX(A17)+1 -> 15 | B18: PJ.80.34 | C18: 高压干线长度含通道 | E18: km | F18: 通用 | H18: =MAX(H17)+1 -> 15 | I18: PJ.02.03.02 | J18: 水景面积 | L18: ㎡ | M18: 住宅 | O18: =MAX(O17)+1 -> 15 | P18: PJ.04.22 | Q18: 行业认证 | S18: - | T18: 集中商业 | CI18: C0200018
A19: =MAX(A18)+1 -> 16 | B19: PJ.02.12 | C19: 车位数 | D19: =AI69+CD96 -> 522.5 | E19: 个 | F19: 通用 | H19: =MAX(H18)+1 -> 16 | I19: PJ.01.15 | J19: 户内装饰面积 | K19: =G69 -> 46191.065 | L19: ㎡ | M19: 住宅 | CI19: C0200019
A20: =MAX(A19)+1 -> 17 | B20: PJ.01.02.01 | C20: 地下车位数 | D20: =AI32+CD72 -> 522.5 | E20: 个 | F20: 通用 | H20: =MAX(H19)+1 -> 17 | I20: PJ.01.17 | J20: 赠送面积 | K20: =H69 -> 0 | L20: ㎡ | M20: 住宅 | CI20: C0200020
A21: =MAX(A20)+1 -> 18 | B21: PJ.02.04 | C21: 机动车单车位面积 （不含地下配套、可售） | D21: =IFERROR((I33+E72)/D20,0) -> 38.912766 | E21: ㎡/个 | F21: 通用 | H21: =MAX(H20)+1 -> 18 | I21: PJ.01.21 | J21: 卖场总面积 （含样板房） | K21: =总指标!K3+1000 -> 1370 | L21: ㎡ | M21: 住宅 | CI21: C0200021
A22: =MAX(A21)+1 -> 19 | B22: PJ.80.08 | C22: 充电桩数量 | D22: =AJ69+CG96 -> 156.75 | E22: (个) | F22: 通用 | H22: =MAX(H21)+1 -> 19 | I22: PJ.02.03.03 | J22: 售楼处面积 | K22: =总指标!K3 -> 370 | L22: ㎡ | M22: 住宅 | CI22: C0200022
A23: =MAX(A22)+1 -> 20 | B23: PJ.80.35 | C23: 停车场出入口数量 | D23: =AK69+CH96 -> 2 | E23: 个 | F23: 通用 | H23: =MAX(H22)+1 -> 20 | I23: PJ.02.04.02 | J23: 样板房数量 | K23: 2 | L23: 个 | M23: 住宅 | CI23: C0200023
A24: =MAX(A23)+1 -> 21 | B24: PJ.01.02.02 | C24: 地下车库-1F层高 | D24: 3.7 | E24: m | F24: 通用 | H24: =MAX(H23)+1 -> 21 | I24: PJ.02.03.04 | J24: 样板房总面积 | K24: =SUM(总指标!J24:J26) -> 319 | L24: ㎡ | M24: 住宅 | CI24: C0200024
A25: =MAX(A24)+1 -> 22 | B25: PJ.01.02.03 | C25: 地下车库-2F层高 | E25: m | F25: 通用 | H25: =MAX(H24)+1 -> 22 | I25: PJ.02.05.01 | J25: 看房通道长度 | L25: m | M25: 住宅 | CI25: C0200025
A26: =MAX(A25)+1 -> 23 | B26: PJ.01.02.04 | C26: 地下车库-3F层高 | E26: m | F26: 通用 | H26: =MAX(H25)+1 -> 23 | I26: PJ.80.33 | J26: 示范区室外面积 | K26: 4600 | L26: ㎡ | M26: 住宅 | CI26: C0200026
CI27: C0200027
CI28: C0200028
A29: 二、信息明细 | CI29: C0200029
A30: 1、住宅 | CI30: C0200030
A31: 分类 | B31: 业态/楼栋 | C31: 建筑面积 （㎡） | D31: 计容面积 （㎡） | E31: 可售面积 （㎡） | F31: 套内面积 （㎡） | G31: 户内装饰面积 （㎡） | H31: 赠送/空腔面积 （㎡） | I31: 建造面积_x000D_ （业态） | J31: 电梯数 | K31: 单个电梯厅面积_x000D_ （m2/个） | L31: 电梯厅数量 | M31: 电梯厅总面积_x000D_ （m2） | N31: 单个大堂面积（m2/个） | O31: 大堂数量 | P31: 大堂总面积_x000D_ （m2） | Q31: 单个标准层连廊面积_x000D_ （m2/个） | R31: 标准层连廊数量 | S31: 标准层连廊总面积_x000D_ （m2） | T31: 单个地下大堂面积_x000D_ （m2/个） | U31: 地下大堂数量 | V31: 地下大堂总面积_x000D_ （m2） | W31: 单个车马厅面积_x000D_ （m2/个） | X31: 车马厅数量 | Y31: 车马厅总面积_x000D_ （m2） | Z31: 架空层面积_x000D_ （m2） | AA31: 楼层数 | AB31: 标准层_x000D_层高_x000D_ （m） | AC31: 户数 | AD31: 卫生间数 | AE31: 墙积比 | AF31: 外墙装饰面积 | AG31: 楼栋数 | AH31: 母婴室 | AI31: 车位数 | AJ31: 充电桩数量 | AK31: 停车场出入口数量 | CI31: C0200031
A32: 业态 | B32: 地下室其他(住宅) | C32: =SUM(C33:C35) -> 21931.92 | D32: =SUM(D33:D35) -> 0 | E32: =SUM(E33:E35) -> 0 | F32: =SUM(F33:F35) -> 0 | G32: =SUM(G33) -> 0 | H32: =SUM(H33:H35) -> 0 | I32: =SUM(I33:I35) -> 21931.92 | AA32: =SUM(AA33) -> 0 | AB32: =SUM(AB33:AB35) -> 0 | AI32: =SUM(AI33) -> 522.5 | AJ32: =SUM(AJ33) -> 156.75 | AK32: =SUM(AK33) -> 2 | CI32: C02_21
A33: 楼栋 | B33: 地下机动车库及机房 | C33: =总指标!E19+总指标!E20 -> 20331.92 | D33: 0 | I33: =C33+H33 -> 20331.92 | AI33: =总指标!E39 -> 522.5 | AJ33: =AI33*0.3 -> 156.75 | AK33: 2 | CI33: C02_21_1
A34: 楼栋 | B34: 地下规划配套 | C34: =总指标!E21 -> 1600 | D34: 0 | I34: =C34+H34 -> 1600 | CI34: C02_21_2
A35: 楼栋 | B35: 地下可售 | C35: =总指标!E22 -> 0 | D35: 0 | E35: =C35 -> 0 | G35: 0 | I35: =C35+H35 -> 0 | CI35: C02_21_3
A36: 业态 | B36: $pname1$ | C36: =SUM(C37:C38) -> 0 | D36: =SUM(D37:D38) -> 0 | E36: =SUM(E37:E38) -> 0 | F36: =SUM(F37:F38) -> 0 | G36: =SUM(G37:G38) -> 0 | H36: =SUM(H37:H38) -> 0 | I36: =SUM(I37:I38) -> 0 | J36: =SUM(J37:J38) -> 0 | K36: =IF(L36=0,0,M36/L36) -> 0 | L36: =SUM(L37:L38) -> 0 | M36: =SUM(M37:M38) -> 0 | N36: =IF(O36=0,0,P36/O36) -> 0 | O36: =SUM(O37:O38) -> 0 | P36: =SUM(P37:P38) -> 0 | Q36: =IF(R36=0,0,S36/R36) -> 0 | R36: =SUM(R37:R38) -> 0 | S36: =SUM(S37:S38) -> 0 | T36: =IF(U36=0,0,V36/U36) -> 0 | U36: =SUM(U37:U38) -> 0 | V36: =SUM(V37:V38) -> 0 | W36: =IF(X36=0,0,Y36/X36) -> 0 | X36: =SUM(X37:X38) -> 0 | Y36: =SUM(Y37:Y38) -> 0 | Z36: =SUM(Z37:Z38) -> 0 | AA36: =SUM(AA37:AA38) -> 0 | AB36: =SUM(AB37:AB38) -> 0 | AC36: =SUM(AC37:AC38) -> 0 | AD36: =SUM(AD37:AD38) -> 0 | AE36: =IFERROR(AF36/C36,0) -> 0 | AF36: =SUM(AF37:AF38) -> 0 | AG36: =SUM(AG37:AG38) -> 0 | AH36: =SUM(AH37:AH38) -> 0 | AI36: =SUM(AI37:AI38) -> 0 | CI36: C02_$pcode1$
A37: 楼栋 | B37: A1-A3栋 | I37: =C37+H37 -> 0 | M37: =K37*L37 -> 0 | P37: =N37*O37 -> 0 | S37: =Q37*R37 -> 0 | V37: =T37*U37 -> 0 | Y37: =W37*X37 -> 0 | AF37: =C37*AE37 -> 0 | CI37: C02_$pcode1$_1
A38: 楼栋 | B38: A4-A6栋 | I38: =C38+H38 -> 0 | M38: =K38*L38 -> 0 | P38: =N38*O38 -> 0 | S38: =Q38*R38 -> 0 | V38: =T38*U38 -> 0 | Y38: =W38*X38 -> 0 | AF38: =C38*AE38 -> 0 | CI38: C02_$pcode1$_2
A39: 业态 | B39: 普通多层 | C39: =SUM(C40:C41) -> 0 | D39: =SUM(D40:D41) -> 0 | E39: =SUM(E40:E41) -> 0 | F39: =SUM(F40:F41) -> 0 | G39: =SUM(G40:G41) -> 0 | H39: =SUM(H40:H41) -> 0 | I39: =SUM(I40:I41) -> 0 | J39: =SUM(J40:J41) -> 0 | K39: =IF(L39=0,0,M39/L39) -> 0 | L39: =SUM(L40:L41) -> 0 | M39: =SUM(M40:M41) -> 0 | N39: =IF(O39=0,0,P39/O39) -> 0 | O39: =SUM(O40:O41) -> 0 | P39: =SUM(P40:P41) -> 0 | Q39: =IF(R39=0,0,S39/R39) -> 0 | R39: =SUM(R40:R41) -> 0 | S39: =SUM(S40:S41) -> 0 | T39: =IF(U39=0,0,V39/U39) -> 0 | U39: =SUM(U40:U41) -> 0 | V39: =SUM(V40:V41) -> 0 | W39: =IF(X39=0,0,Y39/X39) -> 0 | X39: =SUM(X40:X41) -> 0 | Y39: =SUM(Y40:Y41) -> 0 | Z39: =SUM(Z40:Z41) -> 0 | AA39: =SUM(AA40:AA41) -> 0 | AB39: =SUM(AB40:AB41) -> 0 | AC39: =SUM(AC40:AC41) -> 0 | AD39: =SUM(AD40:AD41) -> 0 | AE39: =IFERROR(AF39/C39,0) -> 0 | AF39: =SUM(AF40:AF41) -> 0 | AG39: =SUM(AG40:AG41) -> 0 | AH39: =SUM(AH40:AH41) -> 0 | AI39: =SUM(AI40:AI41) -> 0 | CI39: C02_12
A40: 楼栋 | B40: A1-A3栋 | G40: 0 | H40: 0 | I40: =C40+H40 -> 0 | M40: =K40*L40 -> 0 | P40: =N40*O40 -> 0 | S40: =Q40*R40 -> 0 | V40: =T40*U40 -> 0 | Y40: =W40*X40 -> 0 | AF40: =C40*AE40 -> 0 | CI40: C02_12_1
...

Sheet 03 成本测算（输入）
A1: 成本科目 | B1: 填写信息 | C1: 单位 | D1: 数值 | E1: 配置要求 | F1: 档次/品牌要求 | G1: 设计参考值 | H1: 标准刻度 | I1: 备注说明 | K1: C030001_title
A2: 大宗材料基价 | E2: 测算单价指各业态综合单价 | K2: C030002_1_title
A3: 钢筋 | B3: 主材基价 | C3: 元/kg | E3: 参照20XX年X月螺纹钢（Φ16-25mm，HRB400E）平均价格（国家统计局http://www.stats.gov.cn） | I3: 参照20XX年X月螺纹钢（Φ16-25mm，HRB400E）平均价格（国家统计局http://www.stats.gov.cn） | K3: C030002
A4: 钢板 | B4: 主材基价 | C4: 元/kg | E4: 参照20XX年X月普通中板（20mm，Q235）平均价格（国家统计局http://www.stats.gov.cn） | K4: C030004_1
A5: 混凝土 | B5: 主材基价 | C5: 元/m3 | E5: 参照20XX年X月XX市含泵送C30信息价 | I5: 参照20XX年X月XX市含泵送C30信息价 | K5: C030003
A6: 平板玻璃 | B6: 主材基价 | C6: 元/㎡ | E6: 参照20XX年X月浮法平板玻璃（4.8/5mm）平均价格（国家统计局http://www.stats.gov.cn） | K6: C030006_1
A7: 铝材 | B7: 主材基价 | C7: 元/kg | E7: 参照20XX年X月铝锭（A00）平均价格（国家统计局http://www.stats.gov.cn） | K7: C030007
A8: 铜 | B8: 主材基价 | C8: 元/kg | E8: 参照20XX年X月电解铜（1#）平均价格（国家统计局http://www.stats.gov.cn） | K8: C030008
A9: 单体工程-住宅类 | K9: C030009_title
A10: 主要材料 | K10: C030010_title
A11: 钢筋工程 | B11: 主材单价 | C11: 元/kg | D11: 3.36 | E11: 2025年11月7日苏州市HRB400信息价 | K11: C030011
A12: 混凝土工程 | B12: 主材单价 | C12: 元/m3 | D12: =0.9*387.86+18 -> 367.074 | E12: 2025年10月苏州市泵送C30信息价*0.9+18泵送费 | K12: C030012
A13: 地下室其他(住宅) | K13: C03_21_title
A14: 钢筋工程 | B14: 含量 | C14: kg/m2 | D14: =含量测算!O15 -> 117.94887 | E14: 刻度项目为高层，本项目类似姑苏第小高项目，体量偏小，参考姑苏第项目修正 | H14: 115.544 | I14: 参考竹园路项目，层高3.7m | K14: C03_21_1
A15: 混凝土工程 | B15: 含量 | C15: m3/m2 | D15: =含量测算!O32 -> 1.224269 | E15: 刻度项目为高层，本项目类似姑苏第小高项目，体量偏小，参考姑苏第项目修正 | H15: 1.03 | I15: 参考竹园路项目，层高3.7m | K15: C03_21_2
A16: 土建改造（如有） | B16: 相对面积单方 | C16: 元/m2 | K16: C03_21_3
A17: 人防工程 | B17: 人防占比 | C17: m2/m2 | D17: =总指标!E19/总指标!E18 -> 0.081002484 | H17: 0.2482 | K17: C03_21_4
A18: 充电桩（如有） | B18: 充电桩数量 | C18: 个 | D18: ='02 项目基础信息（输入）'!AJ32 -> 156.75 | E18: 充电桩安装 30% | H18: 711 | I18: （快慢充比例） | K18: C03_21_5
A19: 停车场管理系统 | B19: 出入口数量 | C19: 个 | D19: ='02 项目基础信息（输入）'!AK32 -> 2 | E19: （类型：） | H19: 2 | I19: （类型：） | K19: C03_21_6
A20: 机械停车（如有） | B20: 数量 | C20: 个 | D20: 0 | H20: 0 | K20: C03_21_7
A21: 其他单体工程（如有） | B21: 相对面积单方 | C21: 元/m2 | D21: =15+(800000*2+750*3000+3000*190)/'02 项目基础信息（输入）'!C32 -> 216.53274 | E21: 1、地下室无线信号覆盖；收费标准15元/m2； 2、车库坡道顶盖及坡道装饰按照2个考虑，80万元/个； 4、地库车道吊顶为铝板+灯带+柱面装修；装修单方750 元/m2，扣除车马厅部分，面积3000m2。地面彩石地坪计入地下地坪工程。 5、会所中央车站，单方3000 元/m2；面积 190m2； | H21: 15 | I21: 地下室无线信号覆盖；收费标准15元/m2 | K21: C03_21_8
A22: 普通多层 | K22: C03_12_title
A23: 预制构件影响 | B23: 相对面积单方 | C23: 元/m2 | D23: 0 | E23: 装配面积比例：XX%；PC构件占比：XX%；ALC占比：XX% | K23: C03_12_1
A24: 外墙保温工程 | B24: 保温墙积比 | C24: m2/m2 | D24: 0 | E24: ①大墙面保温材料类型1：( )；②厚度( ) | K24: C03_12_2
B25: 综合单价 | C25: 元/m2 | D25: 0 | E25: ①大墙面保温材料类型2：( )；②厚度( ) | K25: C03_12_3
A26: 土建改造（如有） | B26: 相对面积单方 | C26: 元/m2 | D26: 0 | E26: （改造部位、大致工作量等） | K26: C03_12_4
A27: 太阳能热水器 | B27: 综合单价 | C27: 元/户 | D27: 0 | E27: ①品牌：( ) ；②型号：( ) | K27: C03_12_5
A28: 其他单体工程（如有） | B28: 相对面积单方 | C28: 元/m2 | D28: 0 | E28: （具体什么内容？单方计算过程？） | K28: C03_12_6
A29: 入户门工程 | B29: 每平米户数 | C29: 户/m2 | D29: =IFERROR('02 项目基础信息（输入）'!AC39/'02 项目基础信息（输入）'!C39,0) -> 0 | K29: C03_12_7
B30: 入户门综合单价 | C30: 元/樘 | D30: 0 | E30: ①类型：(钢质门、钢木复合、铸铝门) ；②品牌：( )；③ 型号：( ) | K30: C03_12_8
B31: 入户门锁综合单价 | C31: 元/把 | D31: 0 | E31: ①类型：(电子锁、机械锁) ；②品牌：( )；③ 型号：( ) | K31: C03_12_9
A32: 外立面普通门窗工程_x000D_ （含防火窗） | B32: 窗积比 | C32: m2/m2 | D32: 0 | E32: ①普通窗类型：(塑钢、铝合金（粉末）、铝合金（氟碳）、铝合金（电泳）、铝木复合、其他（手动输入）)；②是否断桥：(是、否)；③是否系统窗：(是、否)；④普通窗玻璃：(普通、中空、中空夹胶、Low-e、中空Low-e、中空夹胶Low-e)；⑤普通窗其他配置(多选)：(纱窗、钢副框、遮阳系统、防坠落) | K32: C03_12_10
B33: 综合单价 | C33: 元/m2 | D33: 0 | E33: ①防火窗类型：(铝合金、镀锌钢、不锈钢、水晶硅、其他（手动输入）)；②是否断桥：(是、否) | K33: C03_12_11
A34: 外立面装饰工程 | B34: 墙积比 | C34: m2/m2 | D34: ='02 项目基础信息（输入）'!AE39 -> 0 | K34: C03_12_12
B35: 外墙单方造价 | C35: 元/m2 | D35: =(D36*D37+D38*D39+D40*D41+D42*D43+D44*D45)/100 -> 0 | K35: C03_12_13
B36: 外墙石材占比 | C36: % | D36: 0 | K36: C03_12_14
B37: 外墙石材综合单价 | C37: 元/m2 | D37: 0 | E37: ①种类：( )；②厚度：( )；③档次：(进口、国产) | K37: C03_12_15
B38: 外墙面砖装饰占比 | C38: % | D38: 0 | K38: C03_12_16
B39: 外墙面砖综合单价 | C39: 元/m2 | D39: 0 | E39: ①类型：(普通砖、劈开砖)；②档次：(进口、国产) | K39: C03_12_17
B40: 外墙铝板占比 | C40: % | D40: 0 | K40: C03_12_18
...

Sheet 04 目标成本控制表
AD1: C040001
A2: 中国海外发展有限公司 | AD2: C040002
A3: 建安成本目标控制表 | AD3: C040003
A4: 项目名称： | C4: 集团商业标准成本 | E4: 建筑面积： | F4: ='02 项目基础信息（输入）'!D4 -> 74626.755 | G4: 建造面积： | H4: ='02 项目基础信息（输入）'!D10 -> 74626.755 | I4: 可租售面积： | J4: ='02 项目基础信息（输入）'!D7+'02 项目基础信息（输入）'!K11 -> 46191.065 | L4: 可租售率： | M4: =IFERROR(J4/'02 项目基础信息（输入）'!D4,0) -> 0.61896119 | N4: 制表日期： | O4: 2024-07-15 19:18:08 | AD4: C040004
A5: 成本科目 | C5: 总价_x000D_ (万元) | D5: 技术经济指标 | J5: 成本属性分类 | Q5: 与项目标准成本刻度差异小计 | U5: 与项目标准刻度差异分析说明 | W5: 项目标准刻度（元/㎡） | AD5: C040005
D6: 相对建筑面积 | F6: 相对建造面积 | H6: 可租售面积 | J6: 总价（万元） | M6: 相对建筑面积单方（元/㎡） | Q6: 合计 | R6: 暂定 | S6: 固定 | T6: 弹性 | W6: 相对建筑面积 | X6: 相对可售面积 | Y6: 相对建筑面积单方（元/㎡） | AD6: C040006
D7: 面积_x000D_ （㎡） | E7: 单价_x000D_ （元/㎡） | F7: 面积_x000D_ （㎡） | G7: 单价_x000D_ （元/㎡） | H7: 面积_x000D_ （㎡） | I7: 单价_x000D_ （元/㎡） | J7: 暂定 | K7: 固定 | L7: 弹性 | M7: 暂定 | N7: 固定 | O7: 弹性 | R7: 小计 | S7: 小计 | T7: 小计 | W7: 单价 | X7: 单价 | Y7: 暂定 | Z7: 固定 | AA7: 弹性 | AD7: C040007
A8: 前期工程 | C8: ='05 成本测算明细'!M4 -> 325.90753 | D8: ='05 成本测算明细'!$N$4 -> 74626.755 | E8: =IF(D8=0,0,C8*10000/D8) -> 43.671675 | F8: ='05 成本测算明细'!$P$4 -> 74626.755 | G8: =IF(F8=0,0,C8*10000/F8) -> 43.671675 | H8: ='02 项目基础信息（输入）'!$E$69 -> 46191.065 | I8: =IF(H8=0,0,C8*10000/H8) -> 70.556403 | J8: =C8 -> 325.90753 | M8: =IFERROR(J8/$F$4*10000,0) -> 43.671675 | Q8: =E8-W8 -> 43.671675 | R8: =M8-Y8 -> 11.235243 | X8: 47.146668 | Y8: 32.436431 | AD8: C041008
A9: 桩基础工程 | C9: ='05 成本测算明细'!M29 -> 1599.5578 | D9: ='05 成本测算明细'!$N$29 -> 74626.755 | E9: =IF(D9=0,0,C9*10000/D9) -> 214.34107 | F9: ='05 成本测算明细'!$P$29 -> 74626.755 | G9: =IF(F9=0,0,C9*10000/F9) -> 214.34107 | H9: ='02 项目基础信息（输入）'!$E$69 -> 46191.065 | I9: =IF(H9=0,0,C9*10000/H9) -> 346.29161 | J9: =C9 -> 1599.5578 | M9: =IFERROR(J9/$F$4*10000,0) -> 214.34107 | Q9: =E9-W9 -> 214.34107 | R9: =M9-Y9 -> 90.682268 | X9: 179.73926 | Y9: 123.6588 | AD9: C042009
A10: 岩土工程 | C10: ='05 成本测算明细'!M47 -> 2510.4349 | D10: ='05 成本测算明细'!$N$47 -> 74626.755 | E10: =IF(D10=0,0,C10*10000/D10) -> 336.39878 | F10: ='05 成本测算明细'!$P$47 -> 74626.755 | G10: =IF(F10=0,0,C10*10000/F10) -> 336.39878 | H10: ='02 项目基础信息（输入）'!$E$69 -> 46191.065 | I10: =IF(H10=0,0,C10*10000/H10) -> 543.4893 | J10: =C10 -> 2510.4349 | M10: =IFERROR(J10/$F$4*10000,0) -> 336.39878 | Q10: =E10-W10 -> 336.39878 | R10: =M10-Y10 -> 149.93878 | X10: 271.02142 | Y10: 186.46 | AD10: C043010
A11: 单体工程 | B11: 小计 | C11: ='05 成本测算明细'!M93 -> 26554.992 | D11: ='05 成本测算明细'!$N$93 -> 74626.755 | E11: =IF(D11=0,0,C11*10000/D11) -> 3558.3742 | F11: ='05 成本测算明细'!$P$93 -> 74626.755 | G11: =IF(F11=0,0,C11*10000/F11) -> 3558.3742 | H11: ='02 项目基础信息（输入）'!$E$69 -> 46191.065 | I11: =IF(H11=0,0,C11*10000/H11) -> 5748.9457 | J11: =SUM(J12:J31) -> 0 | K11: =SUM(K12:K31) -> 16816.793 | L11: =SUM(L12:L31) -> 9738.1989 | N11: =IF($D11=0,0,K11/$D11*10000) -> 2253.4536 | O11: =IF($D11=0,0,L11/$D11*10000) -> 1304.9206 | AD11: C044011
B12: 地下室其他(住宅) | C12: ='05 成本测算明细'!M94 -> 6146.9459 | D12: ='05 成本测算明细'!N94 -> 21931.92 | E12: =IF(D12=0,0,C12*10000/D12) -> 2802.7395 | F12: ='05 成本测算明细'!P94 -> 21931.92 | G12: =IF(F12=0,0,C12*10000/F12) -> 2802.7395 | H12: ='02 项目基础信息（输入）'!$E$32 -> 0 | I12: =IF(H12=0,0,C12*10000/H12) -> 0 | K12: =SUMIF('05 成本测算明细'!$S95:$S253,'04 目标成本控制表'!K$7,'05 成本测算明细'!$M95:$M253) -> 6146.9459 | L12: =SUMIF('05 成本测算明细'!$S95:$S253,'04 目标成本控制表'!L$7,'05 成本测算明细'!$M95:$M253) -> 0 | N12: =IF(D12=0,0,K12/$D12*10000) -> 2802.7395 | O12: =IF($D12=0,0,L12/$D12*10000) -> 0 | Q12: =E12-W12 -> 211.40067 | S12: =N12-Z12 -> 211.40067 | T12: =O12-AA12 -> 0 | W12: 2591.3389 | X12: 0 | Z12: 2591.3389 | AA12: 0 | AD12: C044012_21
B13: $pname1$ | C13: ='05 成本测算明细'!M255 -> 0 | D13: ='05 成本测算明细'!N255 -> 0 | E13: =IF(D13=0,0,C13*10000/D13) -> 0 | F13: ='05 成本测算明细'!P255 -> 0 | G13: =IF(F13=0,0,C13*10000/F13) -> 0 | H13: ='02 项目基础信息（输入）'!$E$36 -> 0 | I13: =IF(H13=0,0,C13*10000/H13) -> 0 | K13: =SUMIF('05 成本测算明细'!$S256:$S446,'04 目标成本控制表'!K$7,'05 成本测算明细'!$M256:$M446) -> 0 | L13: =SUMIF('05 成本测算明细'!$S256:$S446,'04 目标成本控制表'!L$7,'05 成本测算明细'!$M256:$M446) -> 0 | N13: =IF(D13=0,0,K13/$D13*10000) -> 0 | O13: =IF($D13=0,0,L13/$D13*10000) -> 0 | Q13: =E13-W13 -> 0 | S13: =N13-Z13 -> 0 | T13: =O13-AA13 -> 0 | AD13: C044013_$pcode1$
B14: 普通多层 | C14: ='05 成本测算明细'!M448 -> 0 | D14: ='05 成本测算明细'!N448 -> 0 | E14: =IF(D14=0,0,C14*10000/D14) -> 0 | F14: ='05 成本测算明细'!P448 -> 0 | G14: =IF(F14=0,0,C14*10000/F14) -> 0 | H14: ='02 项目基础信息（输入）'!$E$39 -> 0 | I14: =IF(H14=0,0,C14*10000/H14) -> 0 | K14: =SUMIF('05 成本测算明细'!$S449:$S639,'04 目标成本控制表'!K$7,'05 成本测算明细'!$M449:$M639) -> 0 | L14: =SUMIF('05 成本测算明细'!$S449:$S639,'04 目标成本控制表'!L$7,'05 成本测算明细'!$M449:$M639) -> 0 | N14: =IF(D14=0,0,K14/$D14*10000) -> 0 | O14: =IF($D14=0,0,L14/$D14*10000) -> 0 | Q14: =E14-W14 -> -2999.6143 | S14: =N14-Z14 -> -1869.3238 | T14: =O14-AA14 -> -1130.2905 | W14: 2999.6143 | X14: 2999.6143 | Z14: 1869.3238 | AA14: 1130.2905 | AC14: 备注：标准刻度业态，灰色格锁定 | AD14: C044014_12
B15: 小高层 | C15: ='05 成本测算明细'!M641 -> 19954.021 | D15: ='05 成本测算明细'!N641 -> 51879.835 | E15: =IF(D15=0,0,C15*10000/D15) -> 3846.1998 | F15: ='05 成本测算明细'!P641 -> 51879.835 | G15: =IF(F15=0,0,C15*10000/F15) -> 3846.1998 | H15: ='02 项目基础信息（输入）'!$E$42 -> 46191.065 | I15: =IF(H15=0,0,C15*10000/H15) -> 4319.8877 | K15: =SUMIF('05 成本测算明细'!$S642:$S832,'04 目标成本控制表'!K$7,'05 成本测算明细'!$M642:$M832) -> 10215.822 | L15: =SUMIF('05 成本测算明细'!$S642:$S832,'04 目标成本控制表'!L$7,'05 成本测算明细'!$M642:$M832) -> 9738.1989 | N15: =IF(D15=0,0,K15/$D15*10000) -> 1969.1316 | O15: =IF($D15=0,0,L15/$D15*10000) -> 1877.0682 | Q15: =E15-W15 -> 771.81915 | S15: =N15-Z15 -> 10.459995 | T15: =O15-AA15 -> 761.35916 | W15: 3074.3807 | X15: 3074.3807 | Z15: 1958.6716 | AA15: 1115.7091 | AD15: C044015_13
B16: 高层 | C16: ='05 成本测算明细'!M834 -> 0 | D16: ='05 成本测算明细'!N834 -> 0 | E16: =IF(D16=0,0,C16*10000/D16) -> 0 | F16: ='05 成本测算明细'!P834 -> 0 | G16: =IF(F16=0,0,C16*10000/F16) -> 0 | H16: ='02 项目基础信息（输入）'!$E$45 -> 0 | I16: =IF(H16=0,0,C16*10000/H16) -> 0 | K16: =SUMIF('05 成本测算明细'!$S835:$S1025,'04 目标成本控制表'!K$7,'05 成本测算明细'!$M835:$M1025) -> 0 | L16: =SUMIF('05 成本测算明细'!$S835:$S1025,'04 目标成本控制表'!L$7,'05 成本测算明细'!$M835:$M1025) -> 0 | N16: =IF(D16=0,0,K16/$D16*10000) -> 0 | O16: =IF($D16=0,0,L16/$D16*10000) -> 0 | Q16: =E16-W16 -> -2963.3941 | S16: =N16-Z16 -> -1854.1448 | T16: =O16-AA16 -> -1109.2493 | W16: 2963.3941 | X16: 2963.3941 | Z16: 1854.1448 | AA16: 1109.2493 | AD16: C044016_14
B17: $pname2$ | C17: ='05 成本测算明细'!M1027 -> 0 | D17: ='05 成本测算明细'!N1027 -> 0 | E17: =IF(D17=0,0,C17*10000/D17) -> 0 | F17: ='05 成本测算明细'!P1027 -> 0 | G17: =IF(F17=0,0,C17*10000/F17) -> 0 | H17: ='02 项目基础信息（输入）'!$E$48 -> 0 | I17: =IF(H17=0,0,C17*10000/H17) -> 0 | K17: =SUMIF('05 成本测算明细'!$S1028:$S1218,'04 目标成本控制表'!K$7,'05 成本测算明细'!$M1028:$M1218) -> 0 | L17: =SUMIF('05 成本测算明细'!$S1028:$S1218,'04 目标成本控制表'!L$7,'05 成本测算明细'!$M1028:$M1218) -> 0 | N17: =IF(D17=0,0,K17/$D17*10000) -> 0 | O17: =IF($D17=0,0,L17/$D17*10000) -> 0 | Q17: =E17-W17 -> 0 | S17: =N17-Z17 -> 0 | T17: =O17-AA17 -> 0 | AC17: 备注：非标准刻度业态，经办人手填参考项目值，放开 | AD17: C044017_$pcode2$
B18: $pname3$ | C18: ='05 成本测算明细'!M1220 -> 0 | D18: ='05 成本测算明细'!N1220 -> 0 | E18: =IF(D18=0,0,C18*10000/D18) -> 0 | F18: ='05 成本测算明细'!P1220 -> 0 | G18: =IF(F18=0,0,C18*10000/F18) -> 0 | H18: ='02 项目基础信息（输入）'!$E$51 -> 0 | I18: =IF(H18=0,0,C18*10000/H18) -> 0 | K18: =SUMIF('05 成本测算明细'!$S1221:$S1411,'04 目标成本控制表'!K$7,'05 成本测算明细'!$M1221:$M1411) -> 0 | L18: =SUMIF('05 成本测算明细'!$S1221:$S1411,'04 目标成本控制表'!L$7,'05 成本测算明细'!$M1221:$M1411) -> 0 | N18: =IF(D18=0,0,K18/$D18*10000) -> 0 | O18: =IF($D18=0,0,L18/$D18*10000) -> 0 | Q18: =E18-W18 -> 0 | S18: =N18-Z18 -> 0 | T18: =O18-AA18 -> 0 | AD18: C044018_$pcode3$
B19: $pname4$ | C19: ='05 成本测算明细'!M1413 -> 0 | D19: ='05 成本测算明细'!N1413 -> 0 | E19: =IF(D19=0,0,C19*10000/D19) -> 0 | F19: ='05 成本测算明细'!P1413 -> 0 | G19: =IF(F19=0,0,C19*10000/F19) -> 0 | H19: ='02 项目基础信息（输入）'!$E$54 -> 0 | I19: =IF(H19=0,0,C19*10000/H19) -> 0 | K19: =SUMIF('05 成本测算明细'!$S1414:$S1604,'04 目标成本控制表'!K$7,'05 成本测算明细'!$M1414:$M1604) -> 0 | L19: =SUMIF('05 成本测算明细'!$S1414:$S1604,'04 目标成本控制表'!L$7,'05 成本测算明细'!$M1414:$M1604) -> 0 | N19: =IF(D19=0,0,K19/$D19*10000) -> 0 | O19: =IF($D19=0,0,L19/$D19*10000) -> 0 | Q19: =E19-W19 -> 0 | S19: =N19-Z19 -> 0 | T19: =O19-AA19 -> 0 | AD19: C044019_$pcode4$
B20: $pname5$ | C20: ='05 成本测算明细'!M1606 -> 0 | D20: ='05 成本测算明细'!N1606 -> 0 | E20: =IF(D20=0,0,C20*10000/D20) -> 0 | F20: ='05 成本测算明细'!P1606 -> 0 | G20: =IF(F20=0,0,C20*10000/F20) -> 0 | H20: ='02 项目基础信息（输入）'!$E$57 -> 0 | I20: =IF(H20=0,0,C20*10000/H20) -> 0 | K20: =SUMIF('05 成本测算明细'!$S1607:$S1797,'04 目标成本控制表'!K$7,'05 成本测算明细'!$M1607:$M1797) -> 0 | L20: =SUMIF('05 成本测算明细'!$S1607:$S1797,'04 目标成本控制表'!L$7,'05 成本测算明细'!$M1607:$M1797) -> 0 | N20: =IF(D20=0,0,K20/$D20*10000) -> 0 | O20: =IF($D20=0,0,L20/$D20*10000) -> 0 | Q20: =E20-W20 -> 0 | S20: =N20-Z20 -> 0 | T20: =O20-AA20 -> 0 | AD20: C044020_$pcode5$
B21: $pname6$ | C21: ='05 成本测算明细'!M1799 -> 0 | D21: ='05 成本测算明细'!N1799 -> 0 | E21: =IF(D21=0,0,C21*10000/D21) -> 0 | F21: ='05 成本测算明细'!P1799 -> 0 | G21: =IF(F21=0,0,C21*10000/F21) -> 0 | H21: ='02 项目基础信息（输入）'!$E$60 -> 0 | I21: =IF(H21=0,0,C21*10000/H21) -> 0 | K21: =SUMIF('05 成本测算明细'!$S1799:$S1990,'04 目标成本控制表'!K$7,'05 成本测算明细'!$M1799:$M1990) -> 0 | L21: =SUMIF('05 成本测算明细'!$S1799:$S1990,'04 目标成本控制表'!L$7,'05 成本测算明细'!$M1799:$M1990) -> 0 | N21: =IF(D21=0,0,K21/$D21*10000) -> 0 | O21: =IF($D21=0,0,L21/$D21*10000) -> 0 | Q21: =E21-W21 -> 0 | S21: =N21-Z21 -> 0 | T21: =O21-AA21 -> 0 | AD21: C044021_$pcode6$
B22: 幼儿园 | C22: ='05 成本测算明细'!M1992 -> 0 | D22: ='05 成本测算明细'!N1992 -> 0 | E22: =IF(D22=0,0,C22*10000/D22) -> 0 | F22: ='05 成本测算明细'!P1992 -> 0 | G22: =IF(F22=0,0,C22*10000/F22) -> 0 | H22: ='02 项目基础信息（输入）'!$E$63 -> 0 | I22: =IF(H22=0,0,C22*10000/H22) -> 0 | K22: =C22 -> 0 | N22: =IF(D22=0,0,K22/$D22*10000) -> 0 | Q22: =E22-W22 -> 0 | S22: =N22-Z22 -> 0 | T22: =O22-AA22 -> 0 | AD22: C044022_33
B23: 其他公共配套 | C23: ='05 成本测算明细'!M2185 -> 454.02509 | D23: ='05 成本测算明细'!N2185 -> 815 | E23: =IF(D23=0,0,C23*10000/D23) -> 5570.86 | F23: ='05 成本测算明细'!P2185 -> 815 | G23: =IF(F23=0,0,C23*10000/F23) -> 5570.86 | H23: ='02 项目基础信息（输入）'!$E$66 -> 0 | I23: =IF(H23=0,0,C23*10000/H23) -> 0 | K23: =C23 -> 454.02509 | N23: =IF(D23=0,0,K23/$D23*10000) -> 5570.86 | Q23: =E23-W23 -> 5570.86 | S23: =N23-Z23 -> 5570.86 | T23: =O23-AA23 -> 0 | AD23: C044023_36
B24: 地库及机房(商业) | C24: ='05 成本测算明细'!M2378 -> 0 | D24: ='05 成本测算明细'!N2378 -> 0 | E24: =IF(D24=0,0,C24*10000/D24) -> 0 | F24: ='05 成本测算明细'!P2378 -> 0 | G24: =IF(F24=0,0,C24*10000/F24) -> 0 | H24: =D24 -> 0 | I24: =IF(H24=0,0,C24*10000/H24) -> 0 | K24: =SUMIF('05 成本测算明细'!$S2378:$S2484,'04 目标成本控制表'!K$7,'05 成本测算明细'!$M2378:$M2484) -> 0 | L24: =SUMIF('05 成本测算明细'!$S2378:$S2484,'04 目标成本控制表'!L$7,'05 成本测算明细'!$M2378:$M2484) -> 0 | N24: =IF(D24=0,0,K24/$D24*10000) -> 0 | O24: =IF($D24=0,0,L24/$D24*10000) -> 0 | Q24: =E24-W24 -> 0 | S24: =N24-Z24 -> 0 | T24: =O24-AA24 -> 0 | X24: 0 | Z24: 0 | AA24: 0 | AD24: C044024_20012
B25: $pnames01$集中商业 | C25: ='05 成本测算明细'!M2485 -> 0 | D25: ='05 成本测算明细'!N2485 -> 0 | E25: =IF(D25=0,0,C25*10000/D25) -> 0 | F25: ='05 成本测算明细'!P2485 -> 0 | G25: =IF(F25=0,0,C25*10000/F25) -> 0 | H25: =D25 -> 0 | I25: =IF(H25=0,0,C25*10000/H25) -> 0 | K25: =SUMIF('05 成本测算明细'!$S2485:$S2712,'04 目标成本控制表'!K$7,'05 成本测算明细'!$M2485:$M2712) -> 0 | L25: =SUMIF('05 成本测算明细'!$S2485:$S2712,'04 目标成本控制表'!L$7,'05 成本测算明细'!$M2485:$M2712) -> 0 | N25: =IF(D25=0,0,K25/$D25*10000) -> 0 | O25: =IF($D25=0,0,L25/$D25*10000) -> 0 | Q25: =E25-W25 -> 0 | S25: =N25-Z25 -> 0 | T25: =O25-AA25 -> 0 | X25: =I25 -> 0 | Z25: =N25 -> 0 | AA25: =O25 -> 0 | AD25: C044025_$pcodes01$
B26: $pnamex01$写字楼 | C26: ='05 成本测算明细'!M2713 -> 0 | D26: ='05 成本测算明细'!N2713 -> 0 | E26: =IF(D26=0,0,C26*10000/D26) -> 0 | F26: ='05 成本测算明细'!P2713 -> 0 | G26: =IF(F26=0,0,C26*10000/F26) -> 0 | H26: =D26 -> 0 | I26: =IF(H26=0,0,C26*10000/H26) -> 0 | K26: =SUMIF('05 成本测算明细'!$S2713:$S2939,'04 目标成本控制表'!K$7,'05 成本测算明细'!$M2713:$M2939) -> 0 | L26: =SUMIF('05 成本测算明细'!$S2713:$S2939,'04 目标成本控制表'!L$7,'05 成本测算明细'!$M2713:$M2939) -> 0 | N26: =IF(D26=0,0,K26/$D26*10000) -> 0 | O26: =IF($D26=0,0,L26/$D26*10000) -> 0 | Q26: =E26-W26 -> 0 | S26: =N26-Z26 -> 0 | T26: =O26-AA26 -> 0 | X26: =I26 -> 0 | Z26: =N26 -> 0 | AA26: =O26 -> 0 | AD26: C044026_$pcodex01$
B27: $pnamej01$酒店 | C27: ='05 成本测算明细'!M2940 -> 0 | D27: ='05 成本测算明细'!N2940 -> 0 | E27: =IF(D27=0,0,C27*10000/D27) -> 0 | F27: ='05 成本测算明细'!P2940 -> 0 | G27: =IF(F27=0,0,C27*10000/F27) -> 0 | H27: =D27 -> 0 | I27: =IF(H27=0,0,C27*10000/H27) -> 0 | K27: =SUMIF('05 成本测算明细'!$S2940:$S3210,'04 目标成本控制表'!K$7,'05 成本测算明细'!$M2940:$M3210) -> 0 | L27: =SUMIF('05 成本测算明细'!$S2940:$S3210,'04 目标成本控制表'!L$7,'05 成本测算明细'!$M2940:$M3210) -> 0 | N27: =IF(D27=0,0,K27/$D27*10000) -> 0 | O27: =IF($D27=0,0,L27/$D27*10000) -> 0 | Q27: =E27-W27 -> 0 | S27: =N27-Z27 -> 0 | T27: =O27-AA27 -> 0 | X27: =I27 -> 0 | Z27: =N27 -> 0 | AA27: =O27 -> 0 | AD27: C044027_$pcodej01$
B28: $pname7$集中商业 | C28: ='05 成本测算明细'!M3211 -> 0 | D28: ='05 成本测算明细'!N3211 -> 0 | E28: =IF(D28=0,0,C28*10000/D28) -> 0 | F28: ='05 成本测算明细'!P3211 -> 0 | G28: =IF(F28=0,0,C28*10000/F28) -> 0 | H28: =D28 -> 0 | I28: =IF(H28=0,0,C28*10000/H28) -> 0 | K28: =SUMIF('05 成本测算明细'!$S3211:$S3438,'04 目标成本控制表'!K$7,'05 成本测算明细'!$M3211:$M3438) -> 0 | L28: =SUMIF('05 成本测算明细'!$S3211:$S3438,'04 目标成本控制表'!L$7,'05 成本测算明细'!$M3211:$M3438) -> 0 | N28: =IF(D28=0,0,K28/$D28*10000) -> 0 | O28: =IF($D28=0,0,L28/$D28*10000) -> 0 | Q28: =E28-W28 -> 0 | S28: =N28-Z28 -> 0 | T28: =O28-AA28 -> 0 | AD28: C044028_$pcode7$
B29: $pname8$写字楼 | C29: ='05 成本测算明细'!M3439 -> 0 | D29: ='05 成本测算明细'!N3439 -> 0 | E29: =IF(D29=0,0,C29*10000/D29) -> 0 | F29: ='05 成本测算明细'!P3439 -> 0 | G29: =IF(F29=0,0,C29*10000/F29) -> 0 | H29: =D29 -> 0 | I29: =IF(H29=0,0,C29*10000/H29) -> 0 | K29: =SUMIF('05 成本测算明细'!$S3439:$S3665,'04 目标成本控制表'!K$7,'05 成本测算明细'!$M3439:$M3665) -> 0 | L29: =SUMIF('05 成本测算明细'!$S3439:$S3665,'04 目标成本控制表'!L$7,'05 成本测算明细'!$M3439:$M3665) -> 0 | N29: =IF(D29=0,0,K29/$D29*10000) -> 0 | O29: =IF($D29=0,0,L29/$D29*10000) -> 0 | Q29: =E29-W29 -> 0 | S29: =N29-Z29 -> 0 | T29: =O29-AA29 -> 0 | AD29: C044029_$pcode8$
B30: $pname9$写字楼 | C30: ='05 成本测算明细'!M3666 -> 0 | D30: ='05 成本测算明细'!N3666 -> 0 | E30: =IF(D30=0,0,C30*10000/D30) -> 0 | F30: ='05 成本测算明细'!P3666 -> 0 | G30: =IF(F30=0,0,C30*10000/F30) -> 0 | H30: =D30 -> 0 | I30: =IF(H30=0,0,C30*10000/H30) -> 0 | K30: =SUMIF('05 成本测算明细'!$S3666:$S3892,'04 目标成本控制表'!K$7,'05 成本测算明细'!$M3666:$M3892) -> 0 | L30: =SUMIF('05 成本测算明细'!$S3666:$S3892,'04 目标成本控制表'!L$7,'05 成本测算明细'!$M3666:$M3892) -> 0 | N30: =IF(D30=0,0,K30/$D30*10000) -> 0 | O30: =IF($D30=0,0,L30/$D30*10000) -> 0 | Q30: =E30-W30 -> 0 | S30: =N30-Z30 -> 0 | T30: =O30-AA30 -> 0 | AD30: C044030_$pcode9$
B31: $pname10$酒店 | C31: ='05 成本测算明细'!M3893 -> 0 | D31: ='05 成本测算明细'!N3893 -> 0 | E31: =IF(D31=0,0,C31*10000/D31) -> 0 | F31: ='05 成本测算明细'!P3896 -> 0 | G31: =IF(F31=0,0,C31*10000/F31) -> 0 | H31: =D31 -> 0 | I31: =IF(H31=0,0,C31*10000/H31) -> 0 | K31: =SUMIF('05 成本测算明细'!$S3893:$S41717,'04 目标成本控制表'!K$7,'05 成本测算明细'!$M3893:$M4163) -> 0 | L31: =SUMIF('05 成本测算明细'!$S3893:$S4163,'04 目标成本控制表'!L$7,'05 成本测算明细'!$M3893:$M4163) -> 0 | N31: =IF(D31=0,0,K31/$D31*10000) -> 0 | O31: =IF($D31=0,0,L31/$D31*10000) -> 0 | Q31: =E31-W31 -> 0 | S31: =N31-Z31 -> 0 | T31: =O31-AA31 -> 0 | AD31: C044031_$pcode10$
A32: 配套工程 | C32: ='05 成本测算明细'!M4164 -> 3162.253 | D32: ='05 成本测算明细'!N4164 -> 74626.755 | E32: =IF(D32=0,0,C32*10000/D32) -> 423.74253 | F32: ='05 成本测算明细'!P4164 -> 74626.755 | G32: =IF(F32=0,0,C32*10000/F32) -> 423.74253 | H32: ='02 项目基础信息（输入）'!$E$69 -> 46191.065 | I32: =IF(H32=0,0,C32*10000/H32) -> 684.60275 | J32: =C32 -> 3162.253 | M32: =IFERROR(J32/$F$4*10000,0) -> 423.74253 | Q32: =E32-W32 -> 423.74253 | R32: =M32-Y32 -> 30.317855 | X32: 571.84658 | Y32: 393.42467 | AD32: C040032
A33: 室外工程 | C33: ='05 成本测算明细'!M4190 -> 1963.2039 | D33: ='05 成本测算明细'!N4190 -> 18786.64 | E33: =IF(D33=0,0,C33*10000/D33) -> 1045 | F33: =D33 -> 18786.64 | G33: =IF(F33=0,0,C33*10000/F33) -> 1045 | H33: ='02 项目基础信息（输入）'!$E$69 -> 46191.065 | I33: =IF(H33=0,0,C33*10000/H33) -> 425.01811 | L33: =C33 -> 1963.2039 | O33: =IFERROR(L33/$F$4*10000,0) -> 263.06971 | Q33: =E33-W33 -> 1045 | T33: =O33-AA33 -> 83.069708 | X33: 261.63175 | AA33: 180 | AD33: C040033
A34: 户内装饰工程 | B34: 小计 | C34: ='05 成本测算明细'!M4241 -> 13857.319 | D34: ='05 成本测算明细'!N4241 -> 46191.065 | E34: =IF(D34=0,0,C34*10000/D34) -> 3000 | F34: ='05 成本测算明细'!P4241 -> 46191.065 | G34: =IF(F34=0,0,C34*10000/F34) -> 3000 | H34: ='02 项目基础信息（输入）'!E69 -> 46191.065 | I34: =IF(H34=0,0,C34*10000/H34) -> 3000 | AD34: C046034
B35: $pname1$ | C35: ='05 成本测算明细'!M4242 -> 0 | D35: ='05 成本测算明细'!N4242 -> 0 | E35: =IF(D35=0,0,C35*10000/D35) -> 0 | F35: ='05 成本测算明细'!P4242 -> 0 | G35: =IF(F35=0,0,C35*10000/F35) -> 0 | H35: ='02 项目基础信息（输入）'!$E$36 -> 0 | I35: =IF(H35=0,0,C35*10000/H35) -> 0 | AD35: C046035_$pcode1$
B36: 普通多层 | C36: ='05 成本测算明细'!M4243 -> 0 | D36: ='05 成本测算明细'!N4243 -> 0 | E36: =IF(D36=0,0,C36*10000/D36) -> 0 | F36: ='05 成本测算明细'!P4243 -> 0 | G36: =IF(F36=0,0,C36*10000/F36) -> 0 | H36: ='02 项目基础信息（输入）'!$E$39 -> 0 | I36: =IF(H36=0,0,C36*10000/H36) -> 0 | AD36: C046036_12
B37: 小高层 | C37: ='05 成本测算明细'!M4244 -> 13857.319 | D37: ='05 成本测算明细'!N4244 -> 46191.065 | E37: =IF(D37=0,0,C37*10000/D37) -> 3000 | F37: ='05 成本测算明细'!P4244 -> 46191.065 | G37: =IF(F37=0,0,C37*10000/F37) -> 3000 | H37: ='02 项目基础信息（输入）'!$E$42 -> 46191.065 | I37: =IF(H37=0,0,C37*10000/H37) -> 3000 | AD37: C046037_13
B38: 高层 | C38: ='05 成本测算明细'!M4245 -> 0 | D38: ='05 成本测算明细'!N4245 -> 0 | E38: =IF(D38=0,0,C38*10000/D38) -> 0 | F38: ='05 成本测算明细'!P4245 -> 0 | G38: =IF(F38=0,0,C38*10000/F38) -> 0 | H38: ='02 项目基础信息（输入）'!$E$45 -> 0 | I38: =IF(H38=0,0,C38*10000/H38) -> 0 | AD38: C046038_14
B39: $pname2$ | C39: ='05 成本测算明细'!M4246 -> 0 | D39: ='05 成本测算明细'!N4246 -> 0 | E39: =IF(D39=0,0,C39*10000/D39) -> 0 | F39: ='05 成本测算明细'!P4246 -> 0 | G39: =IF(F39=0,0,C39*10000/F39) -> 0 | H39: ='02 项目基础信息（输入）'!$E$48 -> 0 | I39: =IF(H39=0,0,C39*10000/H39) -> 0 | AD39: C046039_$pcode2$
B40: $pname3$ | C40: ='05 成本测算明细'!M4247 -> 0 | D40: ='05 成本测算明细'!N4247 -> 0 | E40: =IF(D40=0,0,C40*10000/D40) -> 0 | F40: ='05 成本测算明细'!P4247 -> 0 | G40: =IF(F40=0,0,C40*10000/F40) -> 0 | H40: ='02 项目基础信息（输入）'!$E$51 -> 0 | I40: =IF(H40=0,0,C40*10000/H40) -> 0 | AD40: C046040_$pcode3$
...

Sheet 05 成本测算明细
A1: 成本科目/测算明细 | C1: 测算基础信息 | F1: 含量/系数 | I1: 工程量 | K1: 综合单价 | M1: 测算成本(E=C*D)_x000D_ (万元) | N1: 相对建筑_x000D_ 面积(I)_x000D_ (㎡) | O1: 相对建筑_x000D_ 面积单方_x000D_ (J=E/I)_x000D_ (元/㎡) | P1: 相对建造_x000D_ 面积(K)_x000D_ (㎡) | Q1: 相对建造_x000D_ 面积单方_x000D_ (L=E/K)_x000D_ (元/㎡) | R1: 备注 | S1: 成本属性
C2: 说明 | D2: 值(A) | E2: 单位 | F2: 说明 | G2: 值(B) | H2: 单位 | I2: 值(C=A*B) | J2: 单位 | K2: 值(D) | L2: 单位
A3: 03建安 | D3: ='02 项目基础信息（输入）'!$D$4 -> 74626.755 | M3: =ROUND(M4+M29+M47+M93+M4164+M4190+M4241+M4252+M4281+M4310,6) -> 53408.719 | N3: ='02 项目基础信息（输入）'!$D$4 -> 74626.755 | O3: =ROUND(IFERROR(M3*10000/N3,0),2) -> 7156.78 | P3: ='02 项目基础信息（输入）'!$H$69+$N$3 -> 74626.755 | Q3: =ROUND(IFERROR(M3*10000/P3,0),2) -> 7156.78 | U3: C03
A4: 03.01前期工程 | C4: 总建筑面积 | D4: ='02 项目基础信息（输入）'!$D$4 -> 74626.755 | E4: ㎡ | M4: =ROUND(M5+M7+M9+M11+M13+M15+M17+M19+M21+M23+M25+M27,6) -> 325.90753 | N4: ='02 项目基础信息（输入）'!$D$4 -> 74626.755 | O4: =ROUND(IFERROR(M4*10000/N4,0),2) -> 43.67 | P4: ='02 项目基础信息（输入）'!$H$69+$N$3 -> 74626.755 | Q4: =ROUND(IFERROR(M4*10000/P4,0),2) -> 43.67 | S4: 暂定 | U4: C03.01
A5: 03.01.01临时供水 | C5: 总建筑面积 | D5: ='02 项目基础信息（输入）'!$D$4 -> 74626.755 | E5: ㎡ | M5: =ROUND(SUM(M6),6) -> 1.492535 | N5: ='02 项目基础信息（输入）'!$D$4 -> 74626.755 | O5: =ROUND(IFERROR(M5*10000/N5,0),2) -> 0.2 | P5: ='02 项目基础信息（输入）'!$H$69+$N$3 -> 74626.755 | Q5: =ROUND(IFERROR(M5*10000/P5,0),2) -> 0.2 | U5: C03.01.01
A6: 03.01.01.01临时供水 | C6: 总建筑面积 | D6: ='02 项目基础信息（输入）'!$D$4 -> 74626.755 | E6: ㎡ | F6: 总建筑面积 | G6: 1 | H6: ㎡/㎡ | I6: ='02 项目基础信息（输入）'!$D$4 -> 74626.755 | J6: ㎡ | K6: 0.2 | L6: 元/㎡ | M6: =ROUND(K6*I6/10000,6) -> 1.492535 | N6: ='02 项目基础信息（输入）'!$D$4 -> 74626.755 | O6: =ROUND(IFERROR(M6*10000/N6,0),2) -> 0.2 | P6: ='02 项目基础信息（输入）'!$H$69+$N$3 -> 74626.755 | Q6: =ROUND(IFERROR(M6*10000/P6,0),2) -> 0.2 | U6: C03.01.01.01
A7: 03.01.02临时排水 | C7: 总建筑面积 | D7: ='02 项目基础信息（输入）'!$D$4 -> 74626.755 | E7: ㎡ | M7: =ROUND(SUM(M8),6) -> 0 | N7: ='02 项目基础信息（输入）'!$D$4 -> 74626.755 | O7: =ROUND(IFERROR(M7*10000/N7,0),2) -> 0 | P7: ='02 项目基础信息（输入）'!$H$69+$N$3 -> 74626.755 | Q7: =ROUND(IFERROR(M7*10000/P7,0),2) -> 0 | U7: C03.01.02
A8: 03.01.02.01临时排水 | C8: 总建筑面积 | D8: ='02 项目基础信息（输入）'!$D$4 -> 74626.755 | E8: ㎡ | F8: 总建筑面积 | G8: 1 | H8: ㎡/㎡ | I8: ='02 项目基础信息（输入）'!$D$4 -> 74626.755 | J8: ㎡ | L8: 元/㎡ | M8: =ROUND(K8*I8/10000,6) -> 0 | N8: ='02 项目基础信息（输入）'!$D$4 -> 74626.755 | O8: =ROUND(IFERROR(M8*10000/N8,0),2) -> 0 | P8: ='02 项目基础信息（输入）'!$H$69+$N$3 -> 74626.755 | Q8: =ROUND(IFERROR(M8*10000/P8,0),2) -> 0 | U8: C03.01.02.01
A9: 03.01.03临时供电 | C9: 总建筑面积 | D9: ='02 项目基础信息（输入）'!$D$4 -> 74626.755 | E9: ㎡ | M9: =ROUND(SUM(M10),6) -> 60 | N9: ='02 项目基础信息（输入）'!$D$4 -> 74626.755 | O9: =ROUND(IFERROR(M9*10000/N9,0),2) -> 8.04 | P9: ='02 项目基础信息（输入）'!$H$69+$N$3 -> 74626.755 | Q9: =ROUND(IFERROR(M9*10000/P9,0),2) -> 8.04 | U9: C03.01.03
A10: 03.01.03.01临时供电 | C10: 总建筑面积 | D10: ='02 项目基础信息（输入）'!$D$4 -> 74626.755 | E10: ㎡ | F10: 总建筑面积 | G10: 1 | H10: ㎡/㎡ | I10: ='02 项目基础信息（输入）'!$D$4 -> 74626.755 | J10: ㎡ | K10: =60*10000/I10 -> 8.040012 | L10: 元/㎡ | M10: =ROUND(K10*I10/10000,6) -> 60 | N10: ='02 项目基础信息（输入）'!$D$4 -> 74626.755 | O10: =ROUND(IFERROR(M10*10000/N10,0),2) -> 8.04 | P10: ='02 项目基础信息（输入）'!$H$69+$N$3 -> 74626.755 | Q10: =ROUND(IFERROR(M10*10000/P10,0),2) -> 8.04 | R10: 2台临电参考禧宸30万/台（售楼处一台，大区施工一台） | U10: C03.01.03.01
A11: 03.01.04临时设施 | C11: 总建筑面积 | D11: ='02 项目基础信息（输入）'!$D$4 -> 74626.755 | E11: ㎡ | M11: =ROUND(SUM(M12),6) -> 71.5 | N11: ='02 项目基础信息（输入）'!$D$4 -> 74626.755 | O11: =ROUND(IFERROR(M11*10000/N11,0),2) -> 9.58 | P11: ='02 项目基础信息（输入）'!$H$69+$N$3 -> 74626.755 | Q11: =ROUND(IFERROR(M11*10000/P11,0),2) -> 9.58 | U11: C03.01.04
A12: 03.01.04.01临时设施 | C12: 总建筑面积 | D12: ='02 项目基础信息（输入）'!$D$4 -> 74626.755 | E12: ㎡ | F12: 总建筑面积 | G12: 1 | H12: ㎡/㎡ | I12: ='02 项目基础信息（输入）'!$D$4 -> 74626.755 | J12: ㎡ | K12: =550*1300/I12 -> 9.5810143 | L12: 元/㎡ | M12: =ROUND(K12*I12/10000,6) -> 71.5 | N12: ='02 项目基础信息（输入）'!$D$4 -> 74626.755 | O12: =ROUND(IFERROR(M12*10000/N12,0),2) -> 9.58 | P12: ='02 项目基础信息（输入）'!$H$69+$N$3 -> 74626.755 | Q12: =ROUND(IFERROR(M12*10000/P12,0),2) -> 9.58 | R12: 年度标单价 1300 元/m2；临时办公区面积暂估 550m2； | U12: C03.01.04.01
A13: 03.01.05临时道路 | C13: 总建筑面积 | D13: ='02 项目基础信息（输入）'!$D$4 -> 74626.755 | E13: ㎡ | M13: =ROUND(SUM(M14),6) -> 16.915 | N13: ='02 项目基础信息（输入）'!$D$4 -> 74626.755 | O13: =ROUND(IFERROR(M13*10000/N13,0),2) -> 2.27 | P13: ='02 项目基础信息（输入）'!$H$69+$N$3 -> 74626.755 | Q13: =ROUND(IFERROR(M13*10000/P13,0),2) -> 2.27 | U13: C03.01.05
A14: 03.01.05.01临时道路 | C14: 总建筑面积 | D14: ='02 项目基础信息（输入）'!$D$4 -> 74626.755 | E14: ㎡ | F14: 总建筑面积 | G14: 1 | H14: ㎡/㎡ | I14: ='02 项目基础信息（输入）'!$D$4 -> 74626.755 | J14: ㎡ | K14: 2.2666134 | L14: 元/㎡ | M14: =ROUND(K14*I14/10000,6) -> 16.915 | N14: ='02 项目基础信息（输入）'!$D$4 -> 74626.755 | O14: =ROUND(IFERROR(M14*10000/N14,0),2) -> 2.27 | P14: ='02 项目基础信息（输入）'!$H$69+$N$3 -> 74626.755 | Q14: =ROUND(IFERROR(M14*10000/P14,0),2) -> 2.27 | U14: C03.01.05.01
A15: 03.01.06临时围墙 | C15: 总建筑面积 | D15: ='02 项目基础信息（输入）'!$D$4 -> 74626.755 | E15: ㎡ | M15: =ROUND(SUM(M16),6) -> 119 | N15: ='02 项目基础信息（输入）'!$D$4 -> 74626.755 | O15: =ROUND(IFERROR(M15*10000/N15,0),2) -> 15.95 | P15: ='02 项目基础信息（输入）'!$H$69+$N$3 -> 74626.755 | Q15: =ROUND(IFERROR(M15*10000/P15,0),2) -> 15.95 | U15: C03.01.06
A16: 03.01.06.01临时围墙 | C16: 总建筑面积 | D16: ='02 项目基础信息（输入）'!$D$4 -> 74626.755 | E16: ㎡ | F16: 总建筑面积 | G16: 1 | H16: ㎡/㎡ | I16: ='02 项目基础信息（输入）'!$D$4 -> 74626.755 | J16: ㎡ | K16: =850*1400/I16 -> 15.946024 | L16: 元/㎡ | M16: =ROUND(K16*I16/10000,6) -> 119 | N16: ='02 项目基础信息（输入）'!$D$4 -> 74626.755 | O16: =ROUND(IFERROR(M16*10000/N16,0),2) -> 15.95 | P16: ='02 项目基础信息（输入）'!$H$69+$N$3 -> 74626.755 | Q16: =ROUND(IFERROR(M16*10000/P16,0),2) -> 15.95 | R16: 高度4m,延米长度850,参考年度标单价1400一延米 | U16: C03.01.06.01
A17: 03.01.07场地平整清理工程 | C17: 总建筑面积 | D17: ='02 项目基础信息（输入）'!$D$4 -> 74626.755 | E17: ㎡ | M17: =ROUND(SUM(M18),6) -> 0 | N17: ='02 项目基础信息（输入）'!$D$4 -> 74626.755 | O17: =ROUND(IFERROR(M17*10000/N17,0),2) -> 0 | P17: ='02 项目基础信息（输入）'!$H$69+$N$3 -> 74626.755 | Q17: =ROUND(IFERROR(M17*10000/P17,0),2) -> 0 | U17: C03.01.07
A18: 03.01.07.01场地平整清理工程 | C18: 总建筑面积 | D18: ='02 项目基础信息（输入）'!$D$4 -> 74626.755 | E18: ㎡ | F18: 总建筑面积 | G18: 1 | H18: ㎡/㎡ | I18: ='02 项目基础信息（输入）'!$D$4 -> 74626.755 | J18: ㎡ | L18: 元/㎡ | M18: =ROUND(K18*I18/10000,6) -> 0 | N18: ='02 项目基础信息（输入）'!$D$4 -> 74626.755 | O18: =ROUND(IFERROR(M18*10000/N18,0),2) -> 0 | P18: ='02 项目基础信息（输入）'!$H$69+$N$3 -> 74626.755 | Q18: =ROUND(IFERROR(M18*10000/P18,0),2) -> 0 | U18: C03.01.07.01
A19: 03.01.08白蚁防治工程 | C19: 总建筑面积 | D19: ='02 项目基础信息（输入）'!$D$4 -> 74626.755 | E19: ㎡ | M19: =ROUND(SUM(M20),6) -> 0 | N19: ='02 项目基础信息（输入）'!$D$4 -> 74626.755 | O19: =ROUND(IFERROR(M19*10000/N19,0),2) -> 0 | P19: ='02 项目基础信息（输入）'!$H$69+$N$3 -> 74626.755 | Q19: =ROUND(IFERROR(M19*10000/P19,0),2) -> 0 | U19: C03.01.08
A20: 03.01.08.01白蚁防治工程 | C20: 总建筑面积 | D20: ='02 项目基础信息（输入）'!$D$4 -> 74626.755 | E20: ㎡ | F20: 总建筑面积 | G20: 1 | H20: ㎡/㎡ | I20: ='02 项目基础信息（输入）'!$D$4 -> 74626.755 | J20: ㎡ | L20: 元/㎡ | M20: =ROUND(K20*I20/10000,6) -> 0 | N20: ='02 项目基础信息（输入）'!$D$4 -> 74626.755 | O20: =ROUND(IFERROR(M20*10000/N20,0),2) -> 0 | P20: ='02 项目基础信息（输入）'!$H$69+$N$3 -> 74626.755 | Q20: =ROUND(IFERROR(M20*10000/P20,0),2) -> 0 | U20: C03.01.08.01
A21: 03.01.09临时看护工程 | C21: 总建筑面积 | D21: ='02 项目基础信息（输入）'!$D$4 -> 74626.755 | E21: ㎡ | M21: =ROUND(SUM(M22),6) -> 0 | N21: ='02 项目基础信息（输入）'!$D$4 -> 74626.755 | O21: =ROUND(IFERROR(M21*10000/N21,0),2) -> 0 | P21: ='02 项目基础信息（输入）'!$H$69+$N$3 -> 74626.755 | Q21: =ROUND(IFERROR(M21*10000/P21,0),2) -> 0 | U21: C03.01.09
A22: 03.01.09.01临时看护工程 | C22: 总建筑面积 | D22: ='02 项目基础信息（输入）'!$D$4 -> 74626.755 | E22: ㎡ | F22: 总建筑面积 | G22: 1 | H22: ㎡/㎡ | I22: ='02 项目基础信息（输入）'!$D$4 -> 74626.755 | J22: ㎡ | L22: 元/㎡ | M22: =ROUND(K22*I22/10000,6) -> 0 | N22: ='02 项目基础信息（输入）'!$D$4 -> 74626.755 | O22: =ROUND(IFERROR(M22*10000/N22,0),2) -> 0 | P22: ='02 项目基础信息（输入）'!$H$69+$N$3 -> 74626.755 | Q22: =ROUND(IFERROR(M22*10000/P22,0),2) -> 0 | U22: C03.01.09.01
A23: 03.01.10红线内管道改造 | C23: 总建筑面积 | D23: ='02 项目基础信息（输入）'!$D$4 -> 74626.755 | E23: ㎡ | M23: =ROUND(SUM(M24),6) -> 0 | N23: ='02 项目基础信息（输入）'!$D$4 -> 74626.755 | O23: =ROUND(IFERROR(M23*10000/N23,0),2) -> 0 | P23: ='02 项目基础信息（输入）'!$H$69+$N$3 -> 74626.755 | Q23: =ROUND(IFERROR(M23*10000/P23,0),2) -> 0 | U23: C03.01.10
A24: 03.01.10.01红线内管道改造 | C24: 总建筑面积 | D24: ='02 项目基础信息（输入）'!$D$4 -> 74626.755 | E24: ㎡ | F24: 总建筑面积 | G24: 1 | H24: ㎡/㎡ | I24: ='02 项目基础信息（输入）'!$D$4 -> 74626.755 | J24: ㎡ | L24: 元/㎡ | M24: =ROUND(K24*I24/10000,6) -> 0 | N24: ='02 项目基础信息（输入）'!$D$4 -> 74626.755 | O24: =ROUND(IFERROR(M24*10000/N24,0),2) -> 0 | P24: ='02 项目基础信息（输入）'!$H$69+$N$3 -> 74626.755 | Q24: =ROUND(IFERROR(M24*10000/P24,0),2) -> 0 | U24: C03.01.10.01
A25: 03.01.11人防军事设施清除 | C25: 总建筑面积 | D25: ='02 项目基础信息（输入）'!$D$4 -> 74626.755 | E25: ㎡ | M25: =ROUND(SUM(M26),6) -> 0 | N25: ='02 项目基础信息（输入）'!$D$4 -> 74626.755 | O25: =ROUND(IFERROR(M25*10000/N25,0),2) -> 0 | P25: ='02 项目基础信息（输入）'!$H$69+$N$3 -> 74626.755 | Q25: =ROUND(IFERROR(M25*10000/P25,0),2) -> 0 | U25: C03.01.11
A26: 03.01.11.01人防军事设施清除 | C26: 总建筑面积 | D26: ='02 项目基础信息（输入）'!$D$4 -> 74626.755 | E26: ㎡ | F26: 总建筑面积 | G26: 1 | H26: ㎡/㎡ | I26: ='02 项目基础信息（输入）'!$D$4 -> 74626.755 | J26: ㎡ | L26: 元/㎡ | M26: =ROUND(K26*I26/10000,6) -> 0 | N26: ='02 项目基础信息（输入）'!$D$4 -> 74626.755 | O26: =ROUND(IFERROR(M26*10000/N26,0),2) -> 0 | P26: ='02 项目基础信息（输入）'!$H$69+$N$3 -> 74626.755 | Q26: =ROUND(IFERROR(M26*10000/P26,0),2) -> 0 | U26: C03.01.11.01
A27: 03.01.12其他前期工程 | C27: 总建筑面积 | D27: ='02 项目基础信息（输入）'!$D$4 -> 74626.755 | E27: ㎡ | M27: =ROUND(SUM(M28),6) -> 57 | N27: ='02 项目基础信息（输入）'!$D$4 -> 74626.755 | O27: =ROUND(IFERROR(M27*10000/N27,0),2) -> 7.64 | P27: ='02 项目基础信息（输入）'!$H$69+$N$3 -> 74626.755 | Q27: =ROUND(IFERROR(M27*10000/P27,0),2) -> 7.64 | U27: C03.01.12
A28: 03.01.12.01其他前期工程 | C28: 总建筑面积 | D28: ='02 项目基础信息（输入）'!$D$4 -> 74626.755 | E28: ㎡ | F28: 总建筑面积 | G28: 1 | H28: ㎡/㎡ | I28: ='02 项目基础信息（输入）'!$D$4 -> 74626.755 | J28: ㎡ | K28: =570000/I28 -> 7.6380114 | L28: 元/㎡ | M28: =ROUND(K28*I28/10000,6) -> 57 | N28: ='02 项目基础信息（输入）'!$D$4 -> 74626.755 | O28: =ROUND(IFERROR(M28*10000/N28,0),2) -> 7.64 | P28: ='02 项目基础信息（输入）'!$H$69+$N$3 -> 74626.755 | Q28: =ROUND(IFERROR(M28*10000/P28,0),2) -> 7.64 | R28: 临时/正式道口开挖涉及绿化、管线、道路等迁改补偿费 30万；临时用地 4.5 亩，第一年租金 9 万，第二年 18 万，合计租金 27 万；生活区租地在总包范围，不考虑 | U28: C03.01.12.01
A29: 03.02桩基础工程 | C29: 总建筑面积 | D29: ='02 项目基础信息（输入）'!$D$4 -> 74626.755 | E29: ㎡ | M29: =ROUND(M30+M41+M43+M45,6) -> 1599.5578 | N29: ='02 项目基础信息（输入）'!$D$4 -> 74626.755 | O29: =ROUND(IFERROR(M29*10000/N29,0),2) -> 214.34 | P29: ='02 项目基础信息（输入）'!$H$69+$N$3 -> 74626.755 | Q29: =ROUND(IFERROR(M29*10000/P29,0),2) -> 214.34 | S29: 暂定 | U29: C03.02
A30: 03.02.01桩基工程 | C30: 总建筑面积 | D30: ='02 项目基础信息（输入）'!$D$4 -> 74626.755 | E30: ㎡ | M30: =ROUND(SUM(M31:M40),6) -> 1476.8522 | N30: ='02 项目基础信息（输入）'!$D$4 -> 74626.755 | O30: =ROUND(IFERROR(M30*10000/N30,0),2) -> 197.9 | P30: ='02 项目基础信息（输入）'!$H$69+$N$3 -> 74626.755 | Q30: =ROUND(IFERROR(M30*10000/P30,0),2) -> 197.9 | U30: C03.02.01
A31: 03.02.01.01试桩工程 | C31: 总建筑面积 | D31: ='02 项目基础信息（输入）'!$D$4 -> 74626.755 | E31: ㎡ | F31: 桩长含量 | G31: =IFERROR(I31/D31,0) -> 0.25937079 | H31: m/㎡ | I31: =桩基!M15 -> 19356 | J31: m | K31: =桩基!H15 -> 762.99453 | L31: 元/m | M31: =ROUND(K31*I31/10000,6) -> 1476.8522 | N31: ='02 项目基础信息（输入）'!$D$4 -> 74626.755 | O31: =ROUND(IFERROR(M31*10000/N31,0),2) -> 197.9 | P31: ='02 项目基础信息（输入）'!$H$69+$N$3 -> 74626.755 | Q31: =ROUND(IFERROR(M31*10000/P31,0),2) -> 197.9 | U31: C03.02.01.01
A32: 03.02.01.02预制混凝土方桩 | C32: 总建筑面积 | D32: ='02 项目基础信息（输入）'!$D$4 -> 74626.755 | E32: ㎡ | F32: 桩长含量 | G32: =IFERROR(I32/D32,0) -> 0 | H32: m/㎡ | J32: m | L32: 元/m | M32: =ROUND(K32*I32/10000,6) -> 0 | N32: ='02 项目基础信息（输入）'!$D$4 -> 74626.755 | O32: =ROUND(IFERROR(M32*10000/N32,0),2) -> 0 | P32: ='02 项目基础信息（输入）'!$H$69+$N$3 -> 74626.755 | Q32: =ROUND(IFERROR(M32*10000/P32,0),2) -> 0 | U32: C03.02.01.02
A33: 03.02.01.03预应力混凝土管桩 | C33: 总建筑面积 | D33: ='02 项目基础信息（输入）'!$D$4 -> 74626.755 | E33: ㎡ | F33: 桩长含量 | G33: =IFERROR(I33/D33,0) -> 0 | H33: m/㎡ | J33: m | L33: 元/m | M33: =ROUND(K33*I33/10000,6) -> 0 | N33: ='02 项目基础信息（输入）'!$D$4 -> 74626.755 | O33: =ROUND(IFERROR(M33*10000/N33,0),2) -> 0 | P33: ='02 项目基础信息（输入）'!$H$69+$N$3 -> 74626.755 | Q33: =ROUND(IFERROR(M33*10000/P33,0),2) -> 0 | U33: C03.02.01.03
A34: 03.02.01.04钢桩 | C34: 总建筑面积 | D34: ='02 项目基础信息（输入）'!$D$4 -> 74626.755 | E34: ㎡ | F34: 桩长含量 | G34: =IFERROR(I34/D34,0) -> 0 | H34: m/㎡ | J34: m | L34: 元/m | M34: =ROUND(K34*I34/10000,6) -> 0 | N34: ='02 项目基础信息（输入）'!$D$4 -> 74626.755 | O34: =ROUND(IFERROR(M34*10000/N34,0),2) -> 0 | P34: ='02 项目基础信息（输入）'!$H$69+$N$3 -> 74626.755 | Q34: =ROUND(IFERROR(M34*10000/P34,0),2) -> 0 | U34: C03.02.01.04
A35: 03.02.01.05钢管桩 | C35: 总建筑面积 | D35: ='02 项目基础信息（输入）'!$D$4 -> 74626.755 | E35: ㎡ | F35: 桩长含量 | G35: =IFERROR(I35/D35,0) -> 0 | H35: m/㎡ | J35: m | L35: 元/m | M35: =ROUND(K35*I35/10000,6) -> 0 | N35: ='02 项目基础信息（输入）'!$D$4 -> 74626.755 | O35: =ROUND(IFERROR(M35*10000/N35,0),2) -> 0 | P35: ='02 项目基础信息（输入）'!$H$69+$N$3 -> 74626.755 | Q35: =ROUND(IFERROR(M35*10000/P35,0),2) -> 0 | U35: C03.02.01.05
